Workbook
Name \p: '[1]FLAREHD-validation'!#REF!
Name \p: '[1]FLAREHD-validation'!#REF!
Name \p: '[1]FLAREHD-validation'!#REF!
Name \p: '[1]FLAREHD-validation'!#REF!
Name \p: '[1]FLAREHD-validation'!#REF!
Name \p: '[1]FLAREHD-validation'!#REF!
Name \p: '[1]FLAREHD-validation'!#REF!
Name \p: '[1]FLAREHD-validation'!#REF!
Name \p: '[1]FLAREHD-validation'!#REF!
Name \p: '[1]FLAREHD-validation'!#REF!
Name \p: '[1]FLAREHD-validation'!#REF!
Name \p: '[1]FLAREHD-validation'!#REF!
Name \p: '[1]FLAREHD-validation'!#REF!
Name \p: '[1]FLAREHD-validation'!#REF!
Name \p: '[1]FLAREHD-validation'!#REF!
Name \p: '[1]FLAREHD-validation'!#REF!
Name \p: '[1]FLAREHD-validation'!#REF!
Name \p: '[1]FLAREHD-validation'!#REF!
Name \p: '[1]FLAREHD-validation'!#REF!
Name \p: '[1]FLAREHD-validation'!#REF!
Name \p: '[1]FLAREHD-validation'!#REF!
Name \p: '[1]FLAREHD-validation'!#REF!
Name \p: '[1]FLAREHD-validation'!#REF!
Name \p: '[1]FLAREHD-validation'!#REF!
Name \p: '[1]FLAREHD-validation'!#REF!
Name \p: '[1]FLAREHD-validation'!#REF!
Name \p: '[1]FLAREHD-validation'!#REF!
Name \p: '[1]FLAREHD-validation'!#REF!
Name \p: '[1]FLAREHD-validation'!#REF!
Name \p: '[1]FLAREHD-validation'!#REF!
Name \p: '[1]FLAREHD-validation'!#REF!
Name \p: '[1]FLAREHD-validation'!#REF!
Name \p: '[1]FLAREHD-validation'!#REF!
Name \p: '[1]FLAREHD-validation'!#REF!
Name \p: '[1]FLAREHD-validation'!#REF!
Name \p: '[1]FLAREHD-validation'!#REF!
Name \p: '[1]FLAREHD-validation'!#REF!
Name \p: '[1]FLAREHD-validation'!#REF!
Name \p: '[1]FLAREHD-validation'!#REF!
Name \p: '[1]FLAREHD-validation'!#REF!
Name \p: '[1]FLAREHD-validation'!#REF!
Name \q: '[1]FLAREHD-validation'!#REF!
Name \q: '[1]FLAREHD-validation'!#REF!
Name \q: '[1]FLAREHD-validation'!#REF!
Name \q: '[1]FLAREHD-validation'!#REF!
Name \q: '[1]FLAREHD-validation'!#REF!
Name \q: '[1]FLAREHD-validation'!#REF!
Name \q: '[1]FLAREHD-validation'!#REF!
Name \q: '[1]FLAREHD-validation'!#REF!
Name \q: '[1]FLAREHD-validation'!#REF!
Name \q: '[1]FLAREHD-validation'!#REF!
Name \q: '[1]FLAREHD-validation'!#REF!
Name \q: '[1]FLAREHD-validation'!#REF!
Name \q: '[1]FLAREHD-validation'!#REF!
Name \q: '[1]FLAREHD-validation'!#REF!
Name \q: '[1]FLAREHD-validation'!#REF!
Name \q: '[1]FLAREHD-validation'!#REF!
Name \q: '[1]FLAREHD-validation'!#REF!
Name \q: '[1]FLAREHD-validation'!#REF!
Name \q: '[1]FLAREHD-validation'!#REF!

Sheet T01
A2: OVERFILL STORAGE TANK SIZING
A3: FUEL TANK
B5: LOCATION | G5: : | H5: IT SURABAYA | Z5: By | AB5: :
B6: PROJECT TITLE | G6: : | H6: Tangki Timbun BBM T01 | Z6: Check | AB6: : | AI6: =PI()*H34 -> 76.626586 | AJ6: =AI6/6 -> 12.771098
H7: BIOSOLAR | Z7: Rev | AB7: :
AJ9: DIMENSION
A11: A. Reference
B12: API 2350 - Overfill Prevention for Storage Tanks in Petroleum Facilities
A14: B. Terms, Definitions, & Acronyms
B15: Critical High (CH) level | H15: : | I15: The highest level in the tank that product can reach without detrimental impacts (i.e. product overflow or tank damage)
B17: High-High tank level alarm (LAHH) | H17: : | I17: An alarm generated when the product level reaches the High-High (HH) tank level
B18: High-High (HH) tank level | H18: : | I18: A level sufficiently below the Critical High (CH) level to enable termination of a receipt or transfer before the Critical High (CH) level is reached
B20: AOPS | H20: : | I20: Automated Overfill Prefention System
B21: CH | H21: : | I21: Critical High
B22: HH | H22: : | I22: High-High tank level
B23: LAHH | H23: : | I23: High-High tank level alarm
B24: FC | H24: : | I24: Foam Chamber
B25: TA | H25: : | I25: Top Angle
A27: A. Purpose
B28: To obtain level of concern storage tank at IT SURABAYA
A30: C. Summary Data
B31: Required Capacity (SAFE) | G31: : | H31: =Sheet1!B20 -> 4899 | K31: kL | R31: Calculation Data
B32: Shell plate height | G32: : | H32: 1.82 | K32: m | R32: Inlet Flow | W32: : | X32: 500 | AA32: m3/hr
C33: Diameter | G33: : | H33: =L33*6/PI() -> 36.287327 | K33: m | L33: 19 | N33: plates (H)
B34: Diameter Taken | G34: : | H34: 24.391 | K34: m | R34: Outlet Flow | W34: : | X34: 300 | AA34: m3/hr
B35: Number of Shell | G35: : | H35: 6 | K35: plates (V) | R35: Response Time | W35: : | X35: 15 | AA35: minutes | AC35: H to HH
B36: Total Tank Height | G36: : | H36: =H32*H35 -> 10.92 | K36: m | R36: Critical High Response | W36: : | X36: 30 | AA36: minutes | AC36: HH to FC
R37: Response Time | W37: : | X37: 15 | AA37: minutes | AC37: L to LL
B39: Critcal High (CH) = Tabel Tangki Tinggi Max Vol. Bersih | L39: : | M39: =U39+U68+U74 -> 11205 | N39: mm | O39: See SAP & Tabel Tangki | U39: =Sheet1!C20 -> 10400 | X39: mm
B40: Low Level (LLLL) = Unpumpable/Dead Stock (Data SAP) | L40: : | M40: =U40/1000 -> 258 | N40: KL | O40: See Data SAP | U40: =Sheet1!M20 -> 258000 | X40: L
M41: =Sheet1!E20 -> 460 | N41: mm | O41: See SAP & Tabel Tangki
AX64: =306+(3*2.54) -> 313.62
B65: Volume per meter of height | J65: : | K65: =PI()*H34^2/4 -> 467.24977 | M65: m3/m | AX65: =PI()*H34^2*0.25*AX64/1000 -> 146.53887
B67: CH to HHLL Volume | J67: : | K67: =X36*X32/60 -> 250 | M67: m3
B68: CH to HHLL Space | J68: : | K68: =K67/K65*1000 -> 535.04575 | M68: mm | R68: taken | T68: : | U68: 536 | W68: mm | Z68: HHLL to CH
T69: : | U69: =U68/1000*K65/X32*60 -> 30.053505 | W69: minutes | Z69: HHLL to CH
B70: Top Shell to HHLL Space | J70: : | K70: =U68 -> 536 | M70: mm
B71: HHLL Height from Bottom | J71: : | K71: =M39-K70 -> 10669 | M71: mm
B73: HHLL to HLL Volume | J73: : | K73: =X32*X35/60 -> 125 | M73: m3
B74: HHLL to HLL Space | J74: : | K74: =K73/K65*1000 -> 267.52287 | M74: mm | R74: taken | T74: : | U74: 269 | W74: mm | Z74: HLL to HHLL
...

Sheet T02
A2: OVERFILL STORAGE TANK SIZING
A3: FUEL TANK
B5: LOCATION | G5: : | H5: IT SURABAYA | Z5: By | AB5: :
B6: PROJECT TITLE | G6: : | H6: Tangki Timbun BBM T02 | Z6: Check | AB6: : | AI6: =PI()*H34 -> 38.157784 | AJ6: =AI6/6 -> 6.3596307
H7: Solar | Z7: Rev | AB7: :
AJ9: DIMENSION
A11: A. Reference
B12: API 2350 - Overfill Prevention for Storage Tanks in Petroleum Facilities
A14: B. Terms, Definitions, & Acronyms
B15: Critical High (CH) level | H15: : | I15: The highest level in the tank that product can reach without detrimental impacts (i.e. product overflow or tank damage)
B17: High-High tank level alarm (LAHH) | H17: : | I17: An alarm generated when the product level reaches the High-High (HH) tank level
B18: High-High (HH) tank level | H18: : | I18: A level sufficiently below the Critical High (CH) level to enable termination of a receipt or transfer before the Critical High (CH) level is reached
B20: AOPS | H20: : | I20: Automated Overfill Prefention System
B21: CH | H21: : | I21: Critical High
B22: HH | H22: : | I22: High-High tank level
B23: LAHH | H23: : | I23: High-High tank level alarm
B24: FC | H24: : | I24: Foam Chamber
B25: TA | H25: : | I25: Top Angle
A27: A. Purpose
B28: To obtain level of concern storage tank at IT SURABAYA
A30: C. Summary Data
B31: Required Capacity (SAFE) | G31: : | H31: =Sheet1!B21 -> 1053 | K31: kL | R31: Calculation Data
B32: Shell plate height | G32: : | H32: 1.82 | K32: m | R32: Inlet Flow | W32: : | X32: 500 | AA32: m3/hr
C33: Diameter | G33: : | H33: =L33*6/PI() -> 36.287327 | K33: m | L33: 19 | N33: plates (H)
B34: Diameter Taken | G34: : | H34: 12.146 | K34: m | R34: Outlet Flow | W34: : | X34: 300 | AA34: m3/hr
B35: Number of Shell | G35: : | H35: 6 | K35: plates (V) | R35: Response Time | W35: : | X35: 15 | AA35: minutes | AC35: H to HH
B36: Total Tank Height | G36: : | H36: =H32*H35 -> 10.92 | K36: m | R36: Critical High Response | W36: : | X36: 30 | AA36: minutes | AC36: HH to FC
R37: Response Time | W37: : | X37: 15 | AA37: minutes | AC37: L to LL
B39: Critcal High (CH) = Tabel Tangki Tinggi Max Vol. Bersih | L39: : | M39: =U39+U68+U74 -> 12250 | N39: mm | O39: See SAP & Tabel Tangki | U39: =Sheet1!C21 -> 9000 | X39: mm
B40: Low Level (LLLL) = Unpumpable/Dead Stock (Data SAP) | L40: : | M40: =U40/1000 -> 31 | N40: KL | O40: See Data SAP | U40: =Sheet1!M21 -> 31000 | X40: L
M41: =Sheet1!E21 -> 200 | N41: mm | O41: See SAP & Tabel Tangki
AX64: =306+(3*2.54) -> 313.62
B65: Volume per meter of height | J65: : | K65: =PI()*H34^2/4 -> 115.86611 | M65: m3/m | AX65: =PI()*H34^2*0.25*AX64/1000 -> 36.33793
B67: CH to HHLL Volume | J67: : | K67: =X36*X32/60 -> 250 | M67: m3
B68: CH to HHLL Space | J68: : | K68: =K67/K65*1000 -> 2157.6628 | M68: mm | R68: taken | T68: : | U68: 2170 | W68: mm | Z68: HHLL to CH
T69: : | U69: =U68/1000*K65/X32*60 -> 30.171536 | W69: minutes | Z69: HHLL to CH
B70: Top Shell to HHLL Space | J70: : | K70: =U68 -> 2170 | M70: mm
B71: HHLL Height from Bottom | J71: : | K71: =M39-K70 -> 10080 | M71: mm
B73: HHLL to HLL Volume | J73: : | K73: =X32*X35/60 -> 125 | M73: m3
B74: HHLL to HLL Space | J74: : | K74: =K73/K65*1000 -> 1078.8314 | M74: mm | R74: taken | T74: : | U74: 1080 | W74: mm | Z74: HLL to HHLL
...

Sheet T03
A2: OVERFILL STORAGE TANK SIZING
A3: FUEL TANK
B5: LOCATION | G5: : | H5: IT SURAAYA | Z5: By | AB5: :
B6: PROJECT TITLE | G6: : | H6: Tangki Timbun BBM T03 | Z6: Check | AB6: : | AI6: =PI()*H34 -> 38.157784 | AJ6: =AI6/6 -> 6.3596307
H7: Solar | Z7: Rev | AB7: :
AJ9: DIMENSION
A11: A. Reference
B12: API 2350 - Overfill Prevention for Storage Tanks in Petroleum Facilities
A14: B. Terms, Definitions, & Acronyms
B15: Critical High (CH) level | H15: : | I15: The highest level in the tank that product can reach without detrimental impacts (i.e. product overflow or tank damage)
B17: High-High tank level alarm (LAHH) | H17: : | I17: An alarm generated when the product level reaches the High-High (HH) tank level
B18: High-High (HH) tank level | H18: : | I18: A level sufficiently below the Critical High (CH) level to enable termination of a receipt or transfer before the Critical High (CH) level is reached
B20: AOPS | H20: : | I20: Automated Overfill Prefention System
B21: CH | H21: : | I21: Critical High
B22: HH | H22: : | I22: High-High tank level
B23: LAHH | H23: : | I23: High-High tank level alarm
B24: FC | H24: : | I24: Foam Chamber
B25: TA | H25: : | I25: Top Angle
A27: A. Purpose
B28: To obtain level of concern storage tank at IT SURABAYA
A30: C. Summary Data
B31: Required Capacity (SAFE) | G31: : | H31: =Sheet1!B22 -> 1756 | K31: kL | R31: Calculation Data
B32: Shell plate height | G32: : | H32: 1.82 | K32: m | R32: Inlet Flow | W32: : | X32: 500 | AA32: m3/hr
C33: Diameter | G33: : | H33: =L33*6/PI() -> 36.287327 | K33: m | L33: 19 | N33: plates (H)
B34: Diameter Taken | G34: : | H34: 12.146 | K34: m | R34: Outlet Flow | W34: : | X34: 250 | AA34: m3/hr
B35: Number of Shell | G35: : | H35: 6 | K35: plates (V) | R35: Response Time | W35: : | X35: 15 | AA35: minutes | AC35: H to HH
B36: Total Tank Height | G36: : | H36: =H32*H35 -> 10.92 | K36: m | R36: Critical High Response | W36: : | X36: 30 | AA36: minutes | AC36: HH to FC
R37: Response Time | W37: : | X37: 15 | AA37: minutes | AC37: L to LL
B39: Critcal High (CH) = Tabel Tangki Tinggi Max Vol. Bersih | L39: : | M39: =U39+U68+U74 -> 13176 | N39: mm | O39: See SAP & Tabel Tangki | U39: =Sheet1!C22 -> 9936 | X39: mm
B40: Low Level (LLLL) = Unpumpable/Dead Stock (Data SAP) | L40: : | M40: =U40/1000 -> 112 | N40: KL | O40: See Data SAP | U40: =Sheet1!M22 -> 112000 | X40: L
M41: =Sheet1!E22 -> 620 | N41: mm | O41: See SAP & Tabel Tangki
AX64: =306+(3*2.54) -> 313.62
B65: Volume per meter of height | J65: : | K65: =PI()*H34^2/4 -> 115.86611 | M65: m3/m | AX65: =PI()*H34^2*0.25*AX64/1000 -> 36.33793
B67: CH to HHLL Volume | J67: : | K67: =X36*X32/60 -> 250 | M67: m3
B68: CH to HHLL Space | J68: : | K68: =K67/K65*1000 -> 2157.6628 | M68: mm | R68: taken | T68: : | U68: 2160 | W68: mm | Z68: HHLL to CH
T69: : | U69: =U68/1000*K65/X32*60 -> 30.032496 | W69: minutes | Z69: HHLL to CH
B70: Top Shell to HHLL Space | J70: : | K70: =U68 -> 2160 | M70: mm
B71: HHLL Height from Bottom | J71: : | K71: =M39-K70 -> 11016 | M71: mm
B73: HHLL to HLL Volume | J73: : | K73: =X32*X35/60 -> 125 | M73: m3
B74: HHLL to HLL Space | J74: : | K74: =K73/K65*1000 -> 1078.8314 | M74: mm | R74: taken | T74: : | U74: 1080 | W74: mm | Z74: HLL to HHLL
...

Sheet T04
A2: OVERFILL STORAGE TANK SIZING
A3: FUEL TANK
B5: LOCATION | G5: : | H5: IT SURABAYA | Z5: By | AB5: :
B6: PROJECT TITLE | G6: : | H6: Tangki Timbun BBM T04 | Z6: Check | AB6: : | AI6: =PI()*H34 -> 38.157784 | AJ6: =AI6/6 -> 6.3596307
H7: AVTUR | Z7: Rev | AB7: :
AJ9: DIMENSION
A11: A. Reference
B12: API 2350 - Overfill Prevention for Storage Tanks in Petroleum Facilities
A14: B. Terms, Definitions, & Acronyms
B15: Critical High (CH) level | H15: : | I15: The highest level in the tank that product can reach without detrimental impacts (i.e. product overflow or tank damage)
B17: High-High tank level alarm (LAHH) | H17: : | I17: An alarm generated when the product level reaches the High-High (HH) tank level
B18: High-High (HH) tank level | H18: : | I18: A level sufficiently below the Critical High (CH) level to enable termination of a receipt or transfer before the Critical High (CH) level is reached
B20: AOPS | H20: : | I20: Automated Overfill Prefention System
B21: CH | H21: : | I21: Critical High
B22: HH | H22: : | I22: High-High tank level
B23: LAHH | H23: : | I23: High-High tank level alarm
B24: FC | H24: : | I24: Foam Chamber
B25: TA | H25: : | I25: Top Angle
A27: A. Purpose
B28: To obtain level of concern storage tank at IT SURABAYA
A30: C. Summary Data
B31: Required Capacity (SAFE) | G31: : | H31: =Sheet1!B23 -> 1048 | K31: kL | R31: Calculation Data
B32: Shell plate height | G32: : | H32: 1.82 | K32: m | R32: Inlet Flow | W32: : | X32: 500 | AA32: m3/hr
C33: Diameter | G33: : | H33: =L33*6/PI() -> 36.287327 | K33: m | L33: 19 | N33: plates (H)
B34: Diameter Taken | G34: : | H34: 12.146 | K34: m | R34: Outlet Flow | W34: : | X34: 250 | AA34: m3/hr
B35: Number of Shell | G35: : | H35: 6 | K35: plates (V) | R35: Response Time | W35: : | X35: 15 | AA35: minutes | AC35: H to HH
B36: Total Tank Height | G36: : | H36: =H32*H35 -> 10.92 | K36: m | R36: Critical High Response | W36: : | X36: 30 | AA36: minutes | AC36: HH to FC
R37: Response Time | W37: : | X37: 15 | AA37: minutes | AC37: L to LL
B39: Critcal High (CH) = Tabel Tangki Tinggi Max Vol. Bersih | L39: : | M39: =U39+U68+U74 -> 12170 | N39: mm | O39: See SAP & Tabel Tangki | U39: =Sheet1!C23 -> 8930 | X39: mm
B40: Low Level (LLLL) = Unpumpable/Dead Stock (Data SAP) | L40: : | M40: =U40/1000 -> 77 | N40: KL | O40: See Data SAP | U40: =Sheet1!M23 -> 77000 | X40: L
M41: =Sheet1!E23 -> 600 | N41: mm | O41: See SAP & Tabel Tangki
AX64: =306+(3*2.54) -> 313.62
B65: Volume per meter of height | J65: : | K65: =PI()*H34^2/4 -> 115.86611 | M65: m3/m | AX65: =PI()*H34^2*0.25*AX64/1000 -> 36.33793
B67: CH to HHLL Volume | J67: : | K67: =X36*X32/60 -> 250 | M67: m3
B68: CH to HHLL Space | J68: : | K68: =K67/K65*1000 -> 2157.6628 | M68: mm | R68: taken | T68: : | U68: 2160 | W68: mm | Z68: HHLL to CH
T69: : | U69: =U68/1000*K65/X32*60 -> 30.032496 | W69: minutes | Z69: HHLL to CH
B70: Top Shell to HHLL Space | J70: : | K70: =U68 -> 2160 | M70: mm
B71: HHLL Height from Bottom | J71: : | K71: =M39-K70 -> 10010 | M71: mm
B73: HHLL to HLL Volume | J73: : | K73: =X32*X35/60 -> 125 | M73: m3
B74: HHLL to HLL Space | J74: : | K74: =K73/K65*1000 -> 1078.8314 | M74: mm | R74: taken | T74: : | U74: 1080 | W74: mm | Z74: HLL to HHLL
...

Sheet T06
A2: OVERFILL STORAGE TANK SIZING
A3: FUEL TANK
B5: LOCATION | G5: : | H5: IT SURABAYA | Z5: By | AB5: :
B6: PROJECT TITLE | G6: : | H6: Tangki Timbun BBM T05 | Z6: Check | AB6: : | AI6: =PI()*H34 -> 75.376233 | AJ6: =AI6/6 -> 12.562705
H7: BIOSOLAR | Z7: Rev | AB7: :
AJ9: DIMENSION
A11: A. Reference
B12: API 2350 - Overfill Prevention for Storage Tanks in Petroleum Facilities
A14: B. Terms, Definitions, & Acronyms
B15: Critical High (CH) level | H15: : | I15: The highest level in the tank that product can reach without detrimental impacts (i.e. product overflow or tank damage)
B17: High-High tank level alarm (LAHH) | H17: : | I17: An alarm generated when the product level reaches the High-High (HH) tank level
B18: High-High (HH) tank level | H18: : | I18: A level sufficiently below the Critical High (CH) level to enable termination of a receipt or transfer before the Critical High (CH) level is reached
B20: AOPS | H20: : | I20: Automated Overfill Prefention System
B21: CH | H21: : | I21: Critical High
B22: HH | H22: : | I22: High-High tank level
B23: LAHH | H23: : | I23: High-High tank level alarm
B24: FC | H24: : | I24: Foam Chamber
B25: TA | H25: : | I25: Top Angle
A27: A. Purpose
B28: To obtain level of concern storage tank at IT SURABAYA
A30: C. Summary Data
B31: Required Capacity (SAFE) | G31: : | H31: =Sheet1!B24 -> 3476 | K31: kL | R31: Calculation Data
B32: Shell plate height | G32: : | H32: 1.82 | K32: m | R32: Inlet Flow | W32: : | X32: 500 | AA32: m3/hr
C33: Diameter | G33: : | H33: =L33*6/PI() -> 36.287327 | K33: m | L33: 19 | N33: plates (H)
B34: Diameter Taken | G34: : | H34: 23.993 | K34: m | R34: Outlet Flow | W34: : | X34: 250 | AA34: m3/hr
B35: Number of Shell | G35: : | H35: 6 | K35: plates (V) | R35: Response Time | W35: : | X35: 15 | AA35: minutes | AC35: H to HH
B36: Total Tank Height | G36: : | H36: =H32*H35 -> 10.92 | K36: m | R36: Critical High Response | W36: : | X36: 30 | AA36: minutes | AC36: HH to FC
R37: Response Time | W37: : | X37: 15 | AA37: minutes | AC37: L to LL
B39: Critcal High (CH) = Tabel Tangki Tinggi Max Vol. Bersih | L39: : | M39: =U39+U68+U74 -> 8332 | N39: mm | O39: See SAP & Tabel Tangki | U39: =Sheet1!C24 -> 7500 | X39: mm
B40: Low Level (LLLL) = Unpumpable/Dead Stock (Data SAP) | L40: : | M40: =U40/1000 -> 381 | N40: KL | O40: See Data SAP | U40: =Sheet1!M24 -> 381000 | X40: L
M41: =Sheet1!E24 -> 652 | N41: mm | O41: See SAP & Tabel Tangki
AX64: =306+(3*2.54) -> 313.62
B65: Volume per meter of height | J65: : | K65: =PI()*H34^2/4 -> 452.12549 | M65: m3/m | AX65: =PI()*H34^2*0.25*AX64/1000 -> 141.7956
B67: CH to HHLL Volume | J67: : | K67: =X36*X32/60 -> 250 | M67: m3
B68: CH to HHLL Space | J68: : | K68: =K67/K65*1000 -> 552.94383 | M68: mm | R68: taken | T68: : | U68: 555 | W68: mm | Z68: HHLL to CH
T69: : | U69: =U68/1000*K65/X32*60 -> 30.111557 | W69: minutes | Z69: HHLL to CH
B70: Top Shell to HHLL Space | J70: : | K70: =U68 -> 555 | M70: mm
B71: HHLL Height from Bottom | J71: : | K71: =M39-K70 -> 7777 | M71: mm
B73: HHLL to HLL Volume | J73: : | K73: =X32*X35/60 -> 125 | M73: m3
B74: HHLL to HLL Space | J74: : | K74: =K73/K65*1000 -> 276.47192 | M74: mm | R74: taken | T74: : | U74: 277 | W74: mm | Z74: HLL to HHLL
...

Sheet T8
A2: OVERFILL STORAGE TANK SIZING
A3: FUEL TANK
B5: LOCATION | G5: : | H5: IT SURABAYA | Z5: By | AB5: :
B6: PROJECT TITLE | G6: : | H6: Tangki Timbun BBM T8 | Z6: Check | AB6: : | AI6: =PI()*H34 -> 109.68871 | AJ6: =AI6/6 -> 18.281451
H7: Pertalite | Z7: Rev | AB7: :
AJ9: DIMENSION
A11: A. Reference
B12: API 2350 - Overfill Prevention for Storage Tanks in Petroleum Facilities
A14: B. Terms, Definitions, & Acronyms
B15: Critical High (CH) level | H15: : | I15: The highest level in the tank that product can reach without detrimental impacts (i.e. product overflow or tank damage)
B17: High-High tank level alarm (LAHH) | H17: : | I17: An alarm generated when the product level reaches the High-High (HH) tank level
B18: High-High (HH) tank level | H18: : | I18: A level sufficiently below the Critical High (CH) level to enable termination of a receipt or transfer before the Critical High (CH) level is reached
B20: AOPS | H20: : | I20: Automated Overfill Prefention System
B21: CH | H21: : | I21: Critical High
B22: HH | H22: : | I22: High-High tank level
B23: LAHH | H23: : | I23: High-High tank level alarm
B24: FC | H24: : | I24: Foam Chamber
B25: TA | H25: : | I25: Top Angle
A27: A. Purpose
B28: To obtain level of concern storage tank at IT Manggis
A30: C. Summary Data
B31: Required Capacity (SAFE) | G31: : | H31: =Sheet1!B25 -> 9809 | K31: kL | R31: Calculation Data
B32: Shell plate height | G32: : | H32: 1.82 | K32: m | R32: Inlet Flow | W32: : | X32: 500 | AA32: m3/hr
C33: Diameter | G33: : | H33: =L33*6/PI() -> 36.287327 | K33: m | L33: 19 | N33: plates (H)
B34: Diameter Taken | G34: : | H34: 34.915 | K34: m | R34: Outlet Flow | W34: : | X34: 300 | AA34: m3/hr
B35: Number of Shell | G35: : | H35: 6 | K35: plates (V) | R35: Response Time | W35: : | X35: 15 | AA35: minutes | AC35: H to HH
B36: Total Tank Height | G36: : | H36: =H32*H35 -> 10.92 | K36: m | R36: Critical High Response | W36: : | X36: 30 | AA36: minutes | AC36: HH to FC
R37: Response Time | W37: : | X37: 15 | AA37: minutes | AC37: L to LL
B39: Critcal High (CH) = Tabel Tangki Tinggi Max Vol. Bersih | L39: : | M39: =U39+U68+U74 -> 10493 | N39: mm | O39: See SAP & Tabel Tangki | U39: =Sheet1!C25 -> 10100 | X39: mm
B40: Low Level (LLLL) = Unpumpable/Dead Stock (Data SAP) | L40: : | M40: =U40/1000 -> 830 | N40: KL | O40: See Data SAP | U40: =Sheet1!M25 -> 830000 | X40: L
M41: =Sheet1!E25 -> 720 | N41: mm | O41: See SAP & Tabel Tangki
AX64: =306+(3*2.54) -> 313.62
B65: Volume per meter of height | J65: : | K65: =PI()*H34^2/4 -> 957.44531 | M65: m3/m | AX65: =PI()*H34^2*0.25*AX64/1000 -> 300.274
B67: CH to HHLL Volume | J67: : | K67: =X36*X32/60 -> 250 | M67: m3
B68: CH to HHLL Space | J68: : | K68: =K67/K65*1000 -> 261.11152 | M68: mm | R68: taken | T68: : | U68: 262 | W68: mm | Z68: HHLL to CH
T69: : | U69: =U68/1000*K65/X32*60 -> 30.10208 | W69: minutes | Z69: HHLL to CH
B70: Top Shell to HHLL Space | J70: : | K70: =U68 -> 262 | M70: mm
B71: HHLL Height from Bottom | J71: : | K71: =M39-K70 -> 10231 | M71: mm
B73: HHLL to HLL Volume | J73: : | K73: =X32*X35/60 -> 125 | M73: m3
B74: HHLL to HLL Space | J74: : | K74: =K73/K65*1000 -> 130.55576 | M74: mm | R74: taken | T74: : | U74: 131 | W74: mm | Z74: HLL to HHLL
...

Sheet T9
A2: OVERFILL STORAGE TANK SIZING
A3: FUEL TANK
B5: LOCATION | G5: : | H5: IT SURABAYA | Z5: By | AB5: :
B6: PROJECT TITLE | G6: : | H6: Tangki Timbun BBM T9 | Z6: Check | AB6: : | AI6: =PI()*H34 -> 79.212117 | AJ6: =AI6/6 -> 13.20202
H7: PERTALITE | Z7: Rev | AB7: :
AJ9: DIMENSION
A11: A. Reference
B12: API 2350 - Overfill Prevention for Storage Tanks in Petroleum Facilities
A14: B. Terms, Definitions, & Acronyms
B15: Critical High (CH) level | H15: : | I15: The highest level in the tank that product can reach without detrimental impacts (i.e. product overflow or tank damage)
B17: High-High tank level alarm (LAHH) | H17: : | I17: An alarm generated when the product level reaches the High-High (HH) tank level
B18: High-High (HH) tank level | H18: : | I18: A level sufficiently below the Critical High (CH) level to enable termination of a receipt or transfer before the Critical High (CH) level is reached
B20: AOPS | H20: : | I20: Automated Overfill Prefention System
B21: CH | H21: : | I21: Critical High
B22: HH | H22: : | I22: High-High tank level
B23: LAHH | H23: : | I23: High-High tank level alarm
B24: FC | H24: : | I24: Foam Chamber
B25: TA | H25: : | I25: Top Angle
A27: A. Purpose
B28: To obtain level of concern storage tank at IT SURABAYA
A30: C. Summary Data
B31: Required Capacity (SAFE) | G31: : | H31: =Sheet1!B26 -> 5216 | K31: kL | R31: Calculation Data
B32: Shell plate height | G32: : | H32: 1.82 | K32: m | R32: Inlet Flow | W32: : | X32: 500 | AA32: m3/hr
C33: Diameter | G33: : | H33: =L33*6/PI() -> 34.377468 | K33: m | L33: 18 | N33: plates (H)
B34: Diameter Taken | G34: : | H34: 25.214 | K34: m | R34: Outlet Flow | W34: : | X34: 300 | AA34: m3/hr
B35: Number of Shell | G35: : | H35: 6 | K35: plates (V) | R35: Response Time | W35: : | X35: 15 | AA35: minutes | AC35: H to HH
B36: Total Tank Height | G36: : | H36: =H32*H35 -> 10.92 | K36: m | R36: Critical High Response | W36: : | X36: 30 | AA36: minutes | AC36: HH to FC
R37: Response Time | W37: : | X37: 15 | AA37: minutes | AC37: L to LL
B39: Critcal High (CH) = Tabel Tangki Tinggi Max Vol. Bersih | L39: : | M39: =U39+U68+U74 -> 11152 | N39: mm | O39: See SAP & Tabel Tangki | U39: =Sheet1!C26 -> 10400 | X39: mm
B40: Low Level (LLLL) = Unpumpable/Dead Stock (Data SAP) | L40: : | M40: =U40/1000 -> 276 | N40: KL | O40: See Data SAP | U40: =Sheet1!M26 -> 276000 | X40: L
M41: =Sheet1!E26 -> 500 | N41: mm | O41: See SAP & Tabel Tangki
AX64: =306+(3*2.54) -> 313.62
B65: Volume per meter of height | J65: : | K65: =PI()*H34^2/4 -> 499.31358 | M65: m3/m | AX65: =PI()*H34^2*0.25*AX64/1000 -> 156.59473
B67: CH to HHLL Volume | J67: : | K67: =X36*X32/60 -> 250 | M67: m3
B68: CH to HHLL Space | J68: : | K68: =K67/K65*1000 -> 500.68736 | M68: mm | R68: taken | T68: : | U68: 501 | W68: mm | Z68: HHLL to CH
T69: : | U69: =U68/1000*K65/X32*60 -> 30.018732 | W69: minutes | Z69: HHLL to CH
B70: Top Shell to HHLL Space | J70: : | K70: =U68 -> 501 | M70: mm
B71: HHLL Height from Bottom | J71: : | K71: =M39-K70 -> 10651 | M71: mm
B73: HHLL to HLL Volume | J73: : | K73: =X32*X35/60 -> 125 | M73: m3
B74: HHLL to HLL Space | J74: : | K74: =K73/K65*1000 -> 250.34368 | M74: mm | R74: taken | T74: : | U74: 251 | W74: mm | Z74: HLL to HHLL
...

Sheet T10
A2: OVERFILL STORAGE TANK SIZING
A3: FUEL TANK
B5: LOCATION | G5: : | H5: IT SURABAYA | Z5: By | AB5: :
B6: PROJECT TITLE | G6: : | H6: Tangki Timbun BBM T10 | Z6: Check | AB6: : | AI6: =PI()*H34 -> 56.564376 | AJ6: =AI6/6 -> 9.427396
H7: PERTAMINA DEX | Z7: Rev | AB7: :
AJ9: DIMENSION
A11: A. Reference
B12: API 2350 - Overfill Prevention for Storage Tanks in Petroleum Facilities
A14: B. Terms, Definitions, & Acronyms
B15: Critical High (CH) level | H15: : | I15: The highest level in the tank that product can reach without detrimental impacts (i.e. product overflow or tank damage)
B17: High-High tank level alarm (LAHH) | H17: : | I17: An alarm generated when the product level reaches the High-High (HH) tank level
B18: High-High (HH) tank level | H18: : | I18: A level sufficiently below the Critical High (CH) level to enable termination of a receipt or transfer before the Critical High (CH) level is reached
B20: AOPS | H20: : | I20: Automated Overfill Prefention System
B21: CH | H21: : | I21: Critical High
B22: HH | H22: : | I22: High-High tank level
B23: LAHH | H23: : | I23: High-High tank level alarm
B24: FC | H24: : | I24: Foam Chamber
B25: TA | H25: : | I25: Top Angle
A27: A. Purpose
B28: To obtain level of concern storage tank at IT SURABAYA
A30: C. Summary Data
B31: Required Capacity (SAFE) | G31: : | H31: =Sheet1!B27 -> 2460 | K31: kL | R31: Calculation Data
B32: Shell plate height | G32: : | H32: 1.82 | K32: m | R32: Inlet Flow | W32: : | X32: 500 | AA32: m3/hr
C33: Diameter | G33: : | H33: =L33*6/PI() -> 36.287327 | K33: m | L33: 19 | N33: plates (H)
B34: Diameter Taken | G34: : | H34: 18.005 | K34: m | R34: Outlet Flow | W34: : | X34: 300 | AA34: m3/hr
B35: Number of Shell | G35: : | H35: 7 | K35: plates (V) | R35: Response Time | W35: : | X35: 15 | AA35: minutes | AC35: H to HH
B36: Total Tank Height | G36: : | H36: =H32*H35 -> 12.74 | K36: m | R36: Critical High Response | W36: : | X36: 30 | AA36: minutes | AC36: HH to FC
R37: Response Time | W37: : | X37: 15 | AA37: minutes | AC37: L to LL
B39: Critcal High (CH) = Tabel Tangki Tinggi Max Vol. Bersih | L39: : | M39: =U39+U68+U74 -> 10978 | N39: mm | O39: See SAP & Tabel Tangki | U39: =Sheet1!C27 -> 9500 | X39: mm
B40: Low Level (LLLL) = Unpumpable/Dead Stock (Data SAP) | L40: : | M40: =U40/1000 -> 169 | N40: KL | O40: See Data SAP | U40: =Sheet1!M27 -> 169000 | X40: L
M41: =Sheet1!E27 -> 500 | N41: mm | O41: See SAP & Tabel Tangki
AX64: =306+(3*2.54) -> 313.62
B65: Volume per meter of height | J65: : | K65: =PI()*H34^2/4 -> 254.6104 | M65: m3/m | AX65: =PI()*H34^2*0.25*AX64/1000 -> 79.850912
B67: CH to HHLL Volume | J67: : | K67: =X36*X32/60 -> 250 | M67: m3
B68: CH to HHLL Space | J68: : | K68: =K67/K65*1000 -> 981.89235 | M68: mm | R68: taken | T68: : | U68: 985 | W68: mm | Z68: HHLL to CH
T69: : | U69: =U68/1000*K65/X32*60 -> 30.094949 | W69: minutes | Z69: HHLL to CH
B70: Top Shell to HHLL Space | J70: : | K70: =U68 -> 985 | M70: mm
B71: HHLL Height from Bottom | J71: : | K71: =M39-K70 -> 9993 | M71: mm
B73: HHLL to HLL Volume | J73: : | K73: =X32*X35/60 -> 125 | M73: m3
B74: HHLL to HLL Space | J74: : | K74: =K73/K65*1000 -> 490.94617 | M74: mm | R74: taken | T74: : | U74: 493 | W74: mm | Z74: HLL to HHLL
...

Sheet T11
A2: OVERFILL STORAGE TANK SIZING
A3: FUEL TANK
B5: LOCATION | G5: : | H5: IT SURABAYA | Z5: By | AB5: :
B6: PROJECT TITLE | G6: : | H6: Tangki Timbun BBM T11 | Z6: Check | AB6: : | AI6: =PI()*H34 -> 114.83778 | AJ6: =AI6/6 -> 19.13963
H7: PERTALITE | Z7: Rev | AB7: :
AJ9: DIMENSION
A11: A. Reference
B12: API 2350 - Overfill Prevention for Storage Tanks in Petroleum Facilities
A14: B. Terms, Definitions, & Acronyms
B15: Critical High (CH) level | H15: : | I15: The highest level in the tank that product can reach without detrimental impacts (i.e. product overflow or tank damage)
B17: High-High tank level alarm (LAHH) | H17: : | I17: An alarm generated when the product level reaches the High-High (HH) tank level
B18: High-High (HH) tank level | H18: : | I18: A level sufficiently below the Critical High (CH) level to enable termination of a receipt or transfer before the Critical High (CH) level is reached
B20: AOPS | H20: : | I20: Automated Overfill Prefention System
B21: CH | H21: : | I21: Critical High
B22: HH | H22: : | I22: High-High tank level
B23: LAHH | H23: : | I23: High-High tank level alarm
B24: FC | H24: : | I24: Foam Chamber
B25: TA | H25: : | I25: Top Angle
A27: A. Purpose
B28: To obtain level of concern storage tank at IT SURABAYA
A30: C. Summary Data
B31: Required Capacity (SAFE) | G31: : | H31: =Sheet1!B28 -> 9342 | K31: kL | R31: Calculation Data
B32: Shell plate height | G32: : | H32: 1.82 | K32: m | R32: Inlet Flow | W32: : | X32: 600 | AA32: m3/hr
C33: Diameter | G33: : | H33: =L33*6/PI() -> 36.287327 | K33: m | L33: 19 | N33: plates (H)
B34: Diameter Taken | G34: : | H34: 36.554 | K34: m | R34: Outlet Flow | W34: : | X34: 300 | AA34: m3/hr
B35: Number of Shell | G35: : | H35: 5 | K35: plates (V) | R35: Response Time | W35: : | X35: 15 | AA35: minutes | AC35: H to HH
B36: Total Tank Height | G36: : | H36: =H32*H35 -> 9.1 | K36: m | R36: Critical High Response | W36: : | X36: 30 | AA36: minutes | AC36: HH to FC
R37: Response Time | W37: : | X37: 15 | AA37: minutes | AC37: L to LL
B39: Critcal High (CH) = Tabel Tangki Tinggi Max Vol. Bersih | L39: : | M39: =U39+U68+U74 -> 9232 | N39: mm | O39: See SAP & Tabel Tangki | U39: =Sheet1!C28 -> 8800 | X39: mm
B40: Low Level (LLLL) = Unpumpable/Dead Stock (Data SAP) | L40: : | M40: =U40/1000 -> 631 | N40: KL | O40: See Data SAP | U40: =Sheet1!M28 -> 631000 | X40: L
M41: =Sheet1!E28 -> 500 | N41: mm | O41: See SAP & Tabel Tangki
AX64: =306+(3*2.54) -> 313.62
B65: Volume per meter of height | J65: : | K65: =PI()*H34^2/4 -> 1049.445 | M65: m3/m | AX65: =PI()*H34^2*0.25*AX64/1000 -> 329.12695
B67: CH to HHLL Volume | J67: : | K67: =X36*X32/60 -> 300 | M67: m3
B68: CH to HHLL Space | J68: : | K68: =K67/K65*1000 -> 285.86538 | M68: mm | R68: taken | T68: : | U68: 287 | W68: mm | Z68: HHLL to CH
T69: : | U69: =U68/1000*K65/X32*60 -> 30.119072 | W69: minutes | Z69: HHLL to CH
B70: Top Shell to HHLL Space | J70: : | K70: =U68 -> 287 | M70: mm
B71: HHLL Height from Bottom | J71: : | K71: =M39-K70 -> 8945 | M71: mm
B73: HHLL to HLL Volume | J73: : | K73: =X32*X35/60 -> 150 | M73: m3
B74: HHLL to HLL Space | J74: : | K74: =K73/K65*1000 -> 142.93269 | M74: mm | R74: taken | T74: : | U74: 145 | W74: mm | Z74: HLL to HHLL
...

Sheet T13
A2: OVERFILL STORAGE TANK SIZING
A3: FUEL TANK
B5: LOCATION | G5: : | H5: IT SURABAYA | Z5: By | AB5: :
B6: PROJECT TITLE | G6: : | H6: Tangki Timbun BBM T13 | Z6: Check | AB6: : | AI6: =PI()*H34 -> 88.024285 | AJ6: =AI6/6 -> 14.670714
H7: MFO | Z7: Rev | AB7: :
AJ9: DIMENSION
A11: A. Reference
B12: API 2350 - Overfill Prevention for Storage Tanks in Petroleum Facilities
A14: B. Terms, Definitions, & Acronyms
B15: Critical High (CH) level | H15: : | I15: The highest level in the tank that product can reach without detrimental impacts (i.e. product overflow or tank damage)
B17: High-High tank level alarm (LAHH) | H17: : | I17: An alarm generated when the product level reaches the High-High (HH) tank level
B18: High-High (HH) tank level | H18: : | I18: A level sufficiently below the Critical High (CH) level to enable termination of a receipt or transfer before the Critical High (CH) level is reached
B20: AOPS | H20: : | I20: Automated Overfill Prefention System
B21: CH | H21: : | I21: Critical High
B22: HH | H22: : | I22: High-High tank level
B23: LAHH | H23: : | I23: High-High tank level alarm
B24: FC | H24: : | I24: Foam Chamber
B25: TA | H25: : | I25: Top Angle
A27: A. Purpose
B28: To obtain level of concern storage tank at IT SURABAYA
A30: C. Summary Data
B31: Required Capacity (SAFE) | G31: : | H31: =Sheet1!B29 -> 5292 | K31: kL | R31: Calculation Data
B32: Shell plate height | G32: : | H32: 1.82 | K32: m | R32: Inlet Flow | W32: : | X32: 450 | AA32: m3/hr
C33: Diameter | G33: : | H33: =L33*6/PI() -> 36.287327 | K33: m | L33: 19 | N33: plates (H)
B34: Diameter Taken | G34: : | H34: 28.019 | K34: m | R34: Outlet Flow | W34: : | X34: 200 | AA34: m3/hr
B35: Number of Shell | G35: : | H35: 6 | K35: plates (V) | R35: Response Time | W35: : | X35: 15 | AA35: minutes | AC35: H to HH
B36: Total Tank Height | G36: : | H36: =H32*H35 -> 10.92 | K36: m | R36: Critical High Response | W36: : | X36: 30 | AA36: minutes | AC36: HH to FC
R37: Response Time | W37: : | X37: 15 | AA37: minutes | AC37: L to LL
B39: Critcal High (CH) = Tabel Tangki Tinggi Max Vol. Bersih | L39: : | M39: =U39+U68+U74 -> 9040 | N39: mm | O39: See SAP & Tabel Tangki | U39: =Sheet1!C29 -> 8490 | X39: mm
B40: Low Level (LLLL) = Unpumpable/Dead Stock (Data SAP) | L40: : | M40: =U40/1000 -> 631 | N40: KL | O40: See Data SAP | U40: =Sheet1!M28 -> 631000 | X40: L
M41: =Sheet1!E29 -> 2446 | N41: mm | O41: See SAP & Tabel Tangki
AX64: =306+(3*2.54) -> 313.62
B65: Volume per meter of height | J65: : | K65: =PI()*H34^2/4 -> 616.58811 | M65: m3/m | AX65: =PI()*H34^2*0.25*AX64/1000 -> 193.37436
B67: CH to HHLL Volume | J67: : | K67: =X36*X32/60 -> 225 | M67: m3
B68: CH to HHLL Space | J68: : | K68: =K67/K65*1000 -> 364.91135 | M68: mm | R68: taken | T68: : | U68: 365 | W68: mm | Z68: HHLL to CH
T69: : | U69: =U68/1000*K65/X32*60 -> 30.007288 | W69: minutes | Z69: HHLL to CH
B70: Top Shell to HHLL Space | J70: : | K70: =U68 -> 365 | M70: mm
B71: HHLL Height from Bottom | J71: : | K71: =M39-K70 -> 8675 | M71: mm
B73: HHLL to HLL Volume | J73: : | K73: =X32*X35/60 -> 112.5 | M73: m3
B74: HHLL to HLL Space | J74: : | K74: =K73/K65*1000 -> 182.45568 | M74: mm | R74: taken | T74: : | U74: 185 | W74: mm | Z74: HLL to HHLL
...

Sheet T14
A2: OVERFILL STORAGE TANK SIZING
A3: FUEL TANK
B5: LOCATION | G5: : | H5: IT SURABAYA | Z5: By | AB5: :
B6: PROJECT TITLE | G6: : | H6: Tangki Timbun BBM T14 | Z6: Check | AB6: : | AI6: =PI()*H34 -> 56.517252 | AJ6: =AI6/6 -> 9.419542
H7: PERTAMAX | Z7: Rev | AB7: :
AJ9: DIMENSION
A11: A. Reference
B12: API 2350 - Overfill Prevention for Storage Tanks in Petroleum Facilities
A14: B. Terms, Definitions, & Acronyms
B15: Critical High (CH) level | H15: : | I15: The highest level in the tank that product can reach without detrimental impacts (i.e. product overflow or tank damage)
B17: High-High tank level alarm (LAHH) | H17: : | I17: An alarm generated when the product level reaches the High-High (HH) tank level
B18: High-High (HH) tank level | H18: : | I18: A level sufficiently below the Critical High (CH) level to enable termination of a receipt or transfer before the Critical High (CH) level is reached
B20: AOPS | H20: : | I20: Automated Overfill Prefention System
B21: CH | H21: : | I21: Critical High
B22: HH | H22: : | I22: High-High tank level
B23: LAHH | H23: : | I23: High-High tank level alarm
B24: FC | H24: : | I24: Foam Chamber
B25: TA | H25: : | I25: Top Angle
A27: A. Purpose
B28: To obtain level of concern storage tank at IT SURABAYA
A30: C. Summary Data
B31: Required Capacity (SAFE) | G31: : | H31: =Sheet1!B30 -> 2467 | K31: kL | R31: Calculation Data
B32: Shell plate height | G32: : | H32: 1.82 | K32: m | R32: Inlet Flow | W32: : | X32: 600 | AA32: m3/hr
C33: Diameter | G33: : | H33: =L33*6/PI() -> 17.188734 | K33: m | L33: 9 | N33: plates (H)
B34: Diameter Taken | G34: : | H34: 17.99 | K34: m | R34: Outlet Flow | W34: : | X34: 300 | AA34: m3/hr
B35: Number of Shell | G35: : | H35: 7 | K35: plates (V) | R35: Response Time | W35: : | X35: 15 | AA35: minutes | AC35: H to HH
B36: Total Tank Height | G36: : | H36: =H32*H35 -> 12.74 | K36: m | R36: Critical High Response | W36: : | X36: 30 | AA36: minutes | AC36: HH to FC
R37: Response Time | W37: : | X37: 15 | AA37: minutes | AC37: L to LL
B39: Critcal High (CH) = Tabel Tangki Tinggi Max Vol. Bersih | L39: : | M39: =U39+U68+U74 -> 11376 | N39: mm | O39: See SAP & Tabel Tangki | U39: =Sheet1!C30 -> 9600 | X39: mm
B40: Low Level (LLLL) = Unpumpable/Dead Stock (Data SAP) | L40: : | M40: =U40/1000 -> 63 | N40: KL | O40: See Data SAP | U40: =Sheet1!M30 -> 63000 | X40: L
M41: =Sheet1!E30 -> 149 | N41: mm | O41: See SAP & Tabel Tangki
AX64: =306+(3*2.54) -> 313.62
B65: Volume per meter of height | J65: : | K65: =PI()*H34^2/4 -> 254.18634 | M65: m3/m | AX65: =PI()*H34^2*0.25*AX64/1000 -> 79.71792
B67: CH to HHLL Volume | J67: : | K67: =X36*X32/60 -> 300 | M67: m3
B68: CH to HHLL Space | J68: : | K68: =K67/K65*1000 -> 1180.2365 | M68: mm | R68: taken | T68: : | U68: 1183 | W68: mm | Z68: HHLL to CH
T69: : | U69: =U68/1000*K65/X32*60 -> 30.070244 | W69: minutes | Z69: HHLL to CH
B70: Top Shell to HHLL Space | J70: : | K70: =U68 -> 1183 | M70: mm
B71: HHLL Height from Bottom | J71: : | K71: =M39-K70 -> 10193 | M71: mm
B73: HHLL to HLL Volume | J73: : | K73: =X32*X35/60 -> 150 | M73: m3
B74: HHLL to HLL Space | J74: : | K74: =K73/K65*1000 -> 590.11826 | M74: mm | R74: taken | T74: : | U74: 593 | W74: mm | Z74: HLL to HHLL
...

Sheet T15
A2: OVERFILL STORAGE TANK SIZING
A3: FUEL TANK
B5: LOCATION | G5: : | H5: IT SURABAYA | Z5: By | AB5: :
B6: PROJECT TITLE | G6: : | H6: Tangki Timbun BBM T15 | Z6: Check | AB6: : | AI6: =PI()*H34 -> 107.24455 | AJ6: =AI6/6 -> 17.874091
H7: PERTALITE | Z7: Rev | AB7: :
AJ9: DIMENSION
A11: A. Reference
B12: API 2350 - Overfill Prevention for Storage Tanks in Petroleum Facilities
A14: B. Terms, Definitions, & Acronyms
B15: Critical High (CH) level | H15: : | I15: The highest level in the tank that product can reach without detrimental impacts (i.e. product overflow or tank damage)
B17: High-High tank level alarm (LAHH) | H17: : | I17: An alarm generated when the product level reaches the High-High (HH) tank level
B18: High-High (HH) tank level | H18: : | I18: A level sufficiently below the Critical High (CH) level to enable termination of a receipt or transfer before the Critical High (CH) level is reached
B20: AOPS | H20: : | I20: Automated Overfill Prefention System
B21: CH | H21: : | I21: Critical High
B22: HH | H22: : | I22: High-High tank level
B23: LAHH | H23: : | I23: High-High tank level alarm
B24: FC | H24: : | I24: Foam Chamber
B25: TA | H25: : | I25: Top Angle
A27: A. Purpose
B28: To obtain level of concern storage tank at IT SURABAYA
A30: C. Summary Data
B31: Required Capacity (SAFE) | G31: : | H31: =Sheet1!B31 -> 9437 | K31: kL | R31: Calculation Data
B32: Shell plate height | G32: : | H32: 1.82 | K32: m | R32: Inlet Flow | W32: : | X32: 500 | AA32: m3/hr
C33: Diameter | G33: : | H33: =L33*6/PI() -> 17.188734 | K33: m | L33: 9 | N33: plates (H)
B34: Diameter Taken | G34: : | H34: 34.137 | K34: m | R34: Outlet Flow | W34: : | X34: 300 | AA34: m3/hr
B35: Number of Shell | G35: : | H35: 6 | K35: plates (V) | R35: Response Time | W35: : | X35: 15 | AA35: minutes | AC35: H to HH
B36: Total Tank Height | G36: : | H36: =H32*H35 -> 10.92 | K36: m | R36: Critical High Response | W36: : | X36: 30 | AA36: minutes | AC36: HH to FC
R37: Response Time | W37: : | X37: 15 | AA37: minutes | AC37: L to LL
B39: Critcal High (CH) = Tabel Tangki Tinggi Max Vol. Bersih | L39: : | M39: =U39+U68+U74 -> 10567 | N39: mm | O39: See SAP & Tabel Tangki | U39: =Sheet1!C31 -> 10156 | X39: mm
B40: Low Level (LLLL) = Unpumpable/Dead Stock (Data SAP) | L40: : | M40: =U40/1000 -> 401 | N40: KL | O40: See Data SAP | U40: =Sheet1!M31 -> 401000 | X40: L
M41: =Sheet1!E31 -> 285 | N41: mm | O41: See SAP & Tabel Tangki
AX64: =306+(3*2.54) -> 313.62
B65: Volume per meter of height | J65: : | K65: =PI()*H34^2/4 -> 915.25179 | M65: m3/m | AX65: =PI()*H34^2*0.25*AX64/1000 -> 287.04127
B67: CH to HHLL Volume | J67: : | K67: =X36*X32/60 -> 250 | M67: m3
B68: CH to HHLL Space | J68: : | K68: =K67/K65*1000 -> 273.14888 | M68: mm | R68: taken | T68: : | U68: 274 | W68: mm | Z68: HHLL to CH
T69: : | U69: =U68/1000*K65/X32*60 -> 30.093479 | W69: minutes | Z69: HHLL to CH
B70: Top Shell to HHLL Space | J70: : | K70: =U68 -> 274 | M70: mm
B71: HHLL Height from Bottom | J71: : | K71: =M39-K70 -> 10293 | M71: mm
B73: HHLL to HLL Volume | J73: : | K73: =X32*X35/60 -> 125 | M73: m3
B74: HHLL to HLL Space | J74: : | K74: =K73/K65*1000 -> 136.57444 | M74: mm | R74: taken | T74: : | U74: 137 | W74: mm | Z74: HLL to HHLL
...

Sheet T16
A2: OVERFILL STORAGE TANK SIZING
A3: FUEL TANK
B5: LOCATION | G5: : | H5: IT SURABAYA | Z5: By | AB5: :
B6: PROJECT TITLE | G6: : | H6: Tangki Timbun BBM T16 | Z6: Check | AB6: : | AI6: =PI()*H34 -> 100.53411 | AJ6: =AI6/6 -> 16.755684
H7: PERTAMAX | Z7: Rev | AB7: :
AJ9: DIMENSION
A11: A. Reference
B12: API 2350 - Overfill Prevention for Storage Tanks in Petroleum Facilities
A14: B. Terms, Definitions, & Acronyms
B15: Critical High (CH) level | H15: : | I15: The highest level in the tank that product can reach without detrimental impacts (i.e. product overflow or tank damage)
B17: High-High tank level alarm (LAHH) | H17: : | I17: An alarm generated when the product level reaches the High-High (HH) tank level
B18: High-High (HH) tank level | H18: : | I18: A level sufficiently below the Critical High (CH) level to enable termination of a receipt or transfer before the Critical High (CH) level is reached
B20: AOPS | H20: : | I20: Automated Overfill Prefention System
B21: CH | H21: : | I21: Critical High
B22: HH | H22: : | I22: High-High tank level
B23: LAHH | H23: : | I23: High-High tank level alarm
B24: FC | H24: : | I24: Foam Chamber
B25: TA | H25: : | I25: Top Angle
A27: A. Purpose
B28: To obtain level of concern storage tank at IT SURABAYA
A30: C. Summary Data
B31: Required Capacity (SAFE) | G31: : | H31: 1910.2678 | K31: kL | R31: Calculation Data
B32: Shell plate height | G32: : | H32: 1.8 | K32: m | R32: Inlet Flow | W32: : | X32: 600 | AA32: m3/hr
C33: Diameter | G33: : | H33: =L33*6/PI() -> 17.188734 | K33: m | L33: 9 | N33: plates (H)
B34: Diameter Taken | G34: : | H34: 32.001 | K34: m | R34: Outlet Flow | W34: : | X34: 300 | AA34: m3/hr
B35: Number of Shell | G35: : | H35: 8 | K35: plates (V) | R35: Response Time | W35: : | X35: 15 | AA35: minutes | AC35: H to HH
B36: Total Tank Height | G36: : | H36: =H32*H35 -> 14.4 | K36: m | R36: Critical High Response | W36: : | X36: 30 | AA36: minutes | AC36: HH to FC
R37: Response Time | W37: : | X37: 15 | AA37: minutes | AC37: L to LL
B39: Critcal High (CH) = Tabel Tangki Tinggi Max Vol. Bersih | L39: : | M39: =U39+U68+U74 -> 10710 | N39: mm | O39: See SAP & Tabel Tangki | U39: =Sheet1!B32 -> 10148 | X39: mm
B40: Low Level (LLLL) = Unpumpable/Dead Stock (Data SAP) | L40: : | M40: =U40/1000 -> 582 | N40: KL | O40: See Data SAP | U40: =Sheet1!M32 -> 582000 | X40: L
M41: =Sheet1!E32 -> 600 | N41: mm | O41: See SAP & Tabel Tangki
AX64: =306+(3*2.54) -> 313.62
B65: Volume per meter of height | J65: : | K65: =PI()*H34^2/4 -> 804.29799 | M65: m3/m | AX65: =PI()*H34^2*0.25*AX64/1000 -> 252.24393
B67: CH to HHLL Volume | J67: : | K67: =X36*X32/60 -> 300 | M67: m3
B68: CH to HHLL Space | J68: : | K68: =K67/K65*1000 -> 372.99609 | M68: mm | R68: taken | T68: : | U68: 374 | W68: mm | Z68: HHLL to CH
T69: : | U69: =U68/1000*K65/X32*60 -> 30.080745 | W69: minutes | Z69: HHLL to CH
B70: Top Shell to HHLL Space | J70: : | K70: =U68 -> 374 | M70: mm
B71: HHLL Height from Bottom | J71: : | K71: =M39-K70 -> 10336 | M71: mm
B73: HHLL to HLL Volume | J73: : | K73: =X32*X35/60 -> 150 | M73: m3
B74: HHLL to HLL Space | J74: : | K74: =K73/K65*1000 -> 186.49804 | M74: mm | R74: taken | T74: : | U74: 188 | W74: mm | Z74: HLL to HHLL
...

Sheet T41
A2: OVERFILL STORAGE TANK SIZING
A3: FUEL TANK
B5: LOCATION | G5: : | H5: IT SURABAYA | Z5: By | AB5: :
B6: PROJECT TITLE | G6: : | H6: Tangki Timbun BBM T41 | Z6: Check | AB6: : | AI6: =PI()*H34 -> 107.21627 | AJ6: =AI6/6 -> 17.869379
H7: PERTAMAX | Z7: Rev | AB7: :
AJ9: DIMENSION
A11: A. Reference
B12: API 2350 - Overfill Prevention for Storage Tanks in Petroleum Facilities
A14: B. Terms, Definitions, & Acronyms
B15: Critical High (CH) level | H15: : | I15: The highest level in the tank that product can reach without detrimental impacts (i.e. product overflow or tank damage)
B17: High-High tank level alarm (LAHH) | H17: : | I17: An alarm generated when the product level reaches the High-High (HH) tank level
B18: High-High (HH) tank level | H18: : | I18: A level sufficiently below the Critical High (CH) level to enable termination of a receipt or transfer before the Critical High (CH) level is reached
B20: AOPS | H20: : | I20: Automated Overfill Prefention System
B21: CH | H21: : | I21: Critical High
B22: HH | H22: : | I22: High-High tank level
B23: LAHH | H23: : | I23: High-High tank level alarm
B24: FC | H24: : | I24: Foam Chamber
B25: TA | H25: : | I25: Top Angle
A27: A. Purpose
B28: To obtain level of concern storage tank at IT SURABAYA
A30: C. Summary Data
B31: Required Capacity (SAFE) | G31: : | H31: =Sheet1!B33 -> 7025 | K31: kL | R31: Calculation Data
B32: Shell plate height | G32: : | H32: 1.8 | K32: m | R32: Inlet Flow | W32: : | X32: 600 | AA32: m3/hr
C33: Diameter | G33: : | H33: =L33*6/PI() -> 17.188734 | K33: m | L33: 9 | N33: plates (H)
B34: Diameter Taken | G34: : | H34: 34.128 | K34: m | R34: Outlet Flow | W34: : | X34: 300 | AA34: m3/hr
B35: Number of Shell | G35: : | H35: 6 | K35: plates (V) | R35: Response Time | W35: : | X35: 15 | AA35: minutes | AC35: H to HH
B36: Total Tank Height | G36: : | H36: =H32*H35 -> 10.8 | K36: m | R36: Critical High Response | W36: : | X36: 30 | AA36: minutes | AC36: HH to FC
R37: Response Time | W37: : | X37: 15 | AA37: minutes | AC37: L to LL
B39: Critcal High (CH) = Tabel Tangki Tinggi Max Vol. Bersih | L39: : | M39: =U39+U68+U74 -> 8145 | N39: mm | O39: See SAP & Tabel Tangki | U39: =Sheet1!C33 -> 7650 | X39: mm
B40: Low Level (LLLL) = Unpumpable/Dead Stock (Data SAP) | L40: : | M40: =U40/1000 -> 994 | N40: KL | O40: See Data SAP | U40: =Sheet1!M33 -> 994000 | X40: L
M41: =Sheet1!E33 -> 1000 | N41: mm | O41: See SAP & Tabel Tangki
AX64: =306+(3*2.54) -> 313.62
B65: Volume per meter of height | J65: : | K65: =PI()*H34^2/4 -> 914.76925 | M65: m3/m | AX65: =PI()*H34^2*0.25*AX64/1000 -> 286.88993
B67: CH to HHLL Volume | J67: : | K67: =X36*X32/60 -> 300 | M67: m3
B68: CH to HHLL Space | J68: : | K68: =K67/K65*1000 -> 327.95156 | M68: mm | R68: taken | T68: : | U68: 330 | W68: mm | Z68: HHLL to CH
T69: : | U69: =U68/1000*K65/X32*60 -> 30.187385 | W69: minutes | Z69: HHLL to CH
B70: Top Shell to HHLL Space | J70: : | K70: =U68 -> 330 | M70: mm
B71: HHLL Height from Bottom | J71: : | K71: =M39-K70 -> 7815 | M71: mm
B73: HHLL to HLL Volume | J73: : | K73: =X32*X35/60 -> 150 | M73: m3
B74: HHLL to HLL Space | J74: : | K74: =K73/K65*1000 -> 163.97578 | M74: mm | R74: taken | T74: : | U74: 165 | W74: mm | Z74: HLL to HHLL
...

Sheet T42
A2: OVERFILL STORAGE TANK SIZING
A3: FUEL TANK
B5: LOCATION | G5: : | H5: IT SURABAYA | Z5: By | AB5: :
B6: PROJECT TITLE | G6: : | H6: Tangki Timbun BBM T42 | Z6: Check | AB6: : | AI6: =PI()*H34 -> 109.79552 | AJ6: =AI6/6 -> 18.299254
H7: PERTAMAX TURBO | Z7: Rev | AB7: :
AJ9: DIMENSION
A11: A. Reference
B12: API 2350 - Overfill Prevention for Storage Tanks in Petroleum Facilities
A14: B. Terms, Definitions, & Acronyms
B15: Critical High (CH) level | H15: : | I15: The highest level in the tank that product can reach without detrimental impacts (i.e. product overflow or tank damage)
B17: High-High tank level alarm (LAHH) | H17: : | I17: An alarm generated when the product level reaches the High-High (HH) tank level
B18: High-High (HH) tank level | H18: : | I18: A level sufficiently below the Critical High (CH) level to enable termination of a receipt or transfer before the Critical High (CH) level is reached
B20: AOPS | H20: : | I20: Automated Overfill Prefention System
B21: CH | H21: : | I21: Critical High
B22: HH | H22: : | I22: High-High tank level
B23: LAHH | H23: : | I23: High-High tank level alarm
B24: FC | H24: : | I24: Foam Chamber
B25: TA | H25: : | I25: Top Angle
A27: A. Purpose
B28: To obtain level of concern storage tank at IT SURABAYA
A30: C. Summary Data
B31: Required Capacity (SAFE) | G31: : | H31: =Sheet1!B34 -> 9905 | K31: kL | R31: Calculation Data
B32: Shell plate height | G32: : | H32: 1.82 | K32: m | R32: Inlet Flow | W32: : | X32: 600 | AA32: m3/hr
C33: Diameter | G33: : | H33: =L33*6/PI() -> 9.5492966 | K33: m | L33: 5 | N33: plates (H)
B34: Diameter Taken | G34: : | H34: 34.949 | K34: m | R34: Outlet Flow | W34: : | X34: 300 | AA34: m3/hr
B35: Number of Shell | G35: : | H35: 6 | K35: plates (V) | R35: Response Time | W35: : | X35: 15 | AA35: minutes | AC35: H to HH
B36: Total Tank Height | G36: : | H36: =H32*H35 -> 10.92 | K36: m | R36: Critical High Response | W36: : | X36: 30 | AA36: minutes | AC36: HH to FC
R37: Response Time | W37: : | X37: 15 | AA37: minutes | AC37: L to LL
B39: Critcal High (CH) = Tabel Tangki Tinggi Max Vol. Bersih | L39: : | M39: =U39+U68+U74 -> 10670 | N39: mm | O39: See SAP & Tabel Tangki | U39: =Sheet1!C34 -> 10200 | X39: mm
B40: Low Level (LLLL) = Unpumpable/Dead Stock (Data SAP) | L40: : | M40: =U40/1000 -> 1270 | N40: KL | O40: See Data SAP | U40: =Sheet1!M34 -> 1270000 | X40: L
M41: =Sheet1!E34 -> 1200 | N41: mm | O41: See SAP & Tabel Tangki
AX64: =306+(3*2.54) -> 313.62
B65: Volume per meter of height | J65: : | K65: =PI()*H34^2/4 -> 959.31092 | M65: m3/m | AX65: =PI()*H34^2*0.25*AX64/1000 -> 300.85909
B67: CH to HHLL Volume | J67: : | K67: =X36*X32/60 -> 300 | M67: m3
B68: CH to HHLL Space | J68: : | K68: =K67/K65*1000 -> 312.72447 | M68: mm | R68: taken | T68: : | U68: 313 | W68: mm | Z68: HHLL to CH
T69: : | U69: =U68/1000*K65/X32*60 -> 30.026432 | W69: minutes | Z69: HHLL to CH
B70: Top Shell to HHLL Space | J70: : | K70: =U68 -> 313 | M70: mm
B71: HHLL Height from Bottom | J71: : | K71: =M39-K70 -> 10357 | M71: mm
B73: HHLL to HLL Volume | J73: : | K73: =X32*X35/60 -> 150 | M73: m3
B74: HHLL to HLL Space | J74: : | K74: =K73/K65*1000 -> 156.36224 | M74: mm | R74: taken | T74: : | U74: 157 | W74: mm | Z74: HLL to HHLL
...

Sheet T44
A2: OVERFILL STORAGE TANK SIZING
A3: FUEL TANK
B5: LOCATION | G5: : | H5: IT SURABAYA | Z5: By | AB5: :
B6: PROJECT TITLE | G6: : | H6: Tangki Timbun BBM T44 | Z6: Check | AB6: : | AI6: =PI()*H34 -> 114.90375 | AJ6: =AI6/6 -> 19.150625
H7: PERTAMAX | Z7: Rev | AB7: :
AJ9: DIMENSION
A11: A. Reference
B12: API 2350 - Overfill Prevention for Storage Tanks in Petroleum Facilities
A14: B. Terms, Definitions, & Acronyms
B15: Critical High (CH) level | H15: : | I15: The highest level in the tank that product can reach without detrimental impacts (i.e. product overflow or tank damage)
B17: High-High tank level alarm (LAHH) | H17: : | I17: An alarm generated when the product level reaches the High-High (HH) tank level
B18: High-High (HH) tank level | H18: : | I18: A level sufficiently below the Critical High (CH) level to enable termination of a receipt or transfer before the Critical High (CH) level is reached
B20: AOPS | H20: : | I20: Automated Overfill Prefention System
B21: CH | H21: : | I21: Critical High
B22: HH | H22: : | I22: High-High tank level
B23: LAHH | H23: : | I23: High-High tank level alarm
B24: FC | H24: : | I24: Foam Chamber
B25: TA | H25: : | I25: Top Angle
A27: A. Purpose
B28: To obtain level of concern storage tank at IT SURABAYA
A30: C. Summary Data
B31: Required Capacity (SAFE) | G31: : | H31: =Sheet1!B35 -> 8234 | K31: kL | R31: Calculation Data
B32: Shell plate height | G32: : | H32: 1.82 | K32: m | R32: Inlet Flow | W32: : | X32: 600 | AA32: m3/hr
C33: Diameter | G33: : | H33: =L33*6/PI() -> 9.5492966 | K33: m | L33: 5 | N33: plates (H)
B34: Diameter Taken | G34: : | H34: 36.575 | K34: m | R34: Outlet Flow | W34: : | X34: 300 | AA34: m3/hr
B35: Number of Shell | G35: : | H35: 5 | K35: plates (V) | R35: Response Time | W35: : | X35: 15 | AA35: minutes | AC35: H to HH
B36: Total Tank Height | G36: : | H36: =H32*H35 -> 9.1 | K36: m | R36: Critical High Response | W36: : | X36: 30 | AA36: minutes | AC36: HH to FC
R37: Response Time | W37: : | X37: 15 | AA37: minutes | AC37: L to LL
B39: Critcal High (CH) = Tabel Tangki Tinggi Max Vol. Bersih | L39: : | M39: =U39+U68+U74 -> 8129 | N39: mm | O39: See SAP & Tabel Tangki | U39: =Sheet1!C35 -> 7700 | X39: mm
B40: Low Level (LLLL) = Unpumpable/Dead Stock (Data SAP) | L40: : | M40: =U40/1000 -> 1408 | N40: KL | O40: See Data SAP | U40: =Sheet1!M35 -> 1408000 | X40: L
M41: =Sheet1!E35 -> 1200 | N41: mm | O41: See SAP & Tabel Tangki
AX64: =306+(3*2.54) -> 313.62
B65: Volume per meter of height | J65: : | K65: =PI()*H34^2/4 -> 1050.6512 | M65: m3/m | AX65: =PI()*H34^2*0.25*AX64/1000 -> 329.50522
B67: CH to HHLL Volume | J67: : | K67: =X36*X32/60 -> 300 | M67: m3
B68: CH to HHLL Space | J68: : | K68: =K67/K65*1000 -> 285.5372 | M68: mm | R68: taken | T68: : | U68: 286 | W68: mm | Z68: HHLL to CH
T69: : | U69: =U68/1000*K65/X32*60 -> 30.048624 | W69: minutes | Z69: HHLL to CH
B70: Top Shell to HHLL Space | J70: : | K70: =U68 -> 286 | M70: mm
B71: HHLL Height from Bottom | J71: : | K71: =M39-K70 -> 7843 | M71: mm
B73: HHLL to HLL Volume | J73: : | K73: =X32*X35/60 -> 150 | M73: m3
B74: HHLL to HLL Space | J74: : | K74: =K73/K65*1000 -> 142.7686 | M74: mm | R74: taken | T74: : | U74: 143 | W74: mm | Z74: HLL to HHLL
...

Sheet T45
A2: OVERFILL STORAGE TANK SIZING
A3: FUEL TANK
B5: LOCATION | G5: : | H5: IT SURABAYA | Z5: By | AB5: :
B6: PROJECT TITLE | G6: : | H6: Tangki Timbun BBM T45 | Z6: Check | AB6: : | AI6: =PI()*H34 -> 76.601454 | AJ6: =AI6/6 -> 12.766909
H7: BIOSOLAR B40 | Z7: Rev | AB7: :
AJ9: DIMENSION
A11: A. Reference
B12: API 2350 - Overfill Prevention for Storage Tanks in Petroleum Facilities
A14: B. Terms, Definitions, & Acronyms
B15: Critical High (CH) level | H15: : | I15: The highest level in the tank that product can reach without detrimental impacts (i.e. product overflow or tank damage)
B17: High-High tank level alarm (LAHH) | H17: : | I17: An alarm generated when the product level reaches the High-High (HH) tank level
B18: High-High (HH) tank level | H18: : | I18: A level sufficiently below the Critical High (CH) level to enable termination of a receipt or transfer before the Critical High (CH) level is reached
B20: AOPS | H20: : | I20: Automated Overfill Prefention System
B21: CH | H21: : | I21: Critical High
B22: HH | H22: : | I22: High-High tank level
B23: LAHH | H23: : | I23: High-High tank level alarm
B24: FC | H24: : | I24: Foam Chamber
B25: TA | H25: : | I25: Top Angle
A27: A. Purpose
B28: To obtain level of concern storage tank at IT SURABAYA
A30: C. Summary Data
B31: Required Capacity (SAFE) | G31: : | H31: =Sheet1!B36 -> 4693 | K31: kL | R31: Calculation Data
B32: Shell plate height | G32: : | H32: 1.82 | K32: m | R32: Inlet Flow | W32: : | X32: 500 | AA32: m3/hr
C33: Diameter | G33: : | H33: =L33*6/PI() -> 9.5492966 | K33: m | L33: 5 | N33: plates (H)
B34: Diameter Taken | G34: : | H34: 24.383 | K34: m | R34: Outlet Flow | W34: : | X34: 300 | AA34: m3/hr
B35: Number of Shell | G35: : | H35: 6 | K35: plates (V) | R35: Response Time | W35: : | X35: 15 | AA35: minutes | AC35: H to HH
B36: Total Tank Height | G36: : | H36: =H32*H35 -> 10.92 | K36: m | R36: Critical High Response | W36: : | X36: 30 | AA36: minutes | AC36: HH to FC
R37: Response Time | W37: : | X37: 15 | AA37: minutes | AC37: L to LL
B39: Critcal High (CH) = Tabel Tangki Tinggi Max Vol. Bersih | L39: : | M39: =U39+U68+U74 -> 10805 | N39: mm | O39: See SAP & Tabel Tangki | U39: =Sheet1!C36 -> 10000 | X39: mm
B40: Low Level (LLLL) = Unpumpable/Dead Stock (Data SAP) | L40: : | M40: =U40/1000 -> 311 | N40: KL | O40: See Data SAP | U40: =Sheet1!M36 -> 311000 | X40: L
M41: =Sheet1!E36 -> 600 | N41: mm | O41: See SAP & Tabel Tangki
AX64: =306+(3*2.54) -> 313.62
B65: Volume per meter of height | J65: : | K65: =PI()*H34^2/4 -> 466.94331 | M65: m3/m | AX65: =PI()*H34^2*0.25*AX64/1000 -> 146.44276
B67: CH to HHLL Volume | J67: : | K67: =X36*X32/60 -> 250 | M67: m3
B68: CH to HHLL Space | J68: : | K68: =K67/K65*1000 -> 535.3969 | M68: mm | R68: taken | T68: : | U68: 537 | W68: mm | Z68: HHLL to CH
T69: : | U69: =U68/1000*K65/X32*60 -> 30.089827 | W69: minutes | Z69: HHLL to CH
B70: Top Shell to HHLL Space | J70: : | K70: =U68 -> 537 | M70: mm
B71: HHLL Height from Bottom | J71: : | K71: =M39-K70 -> 10268 | M71: mm
B73: HHLL to HLL Volume | J73: : | K73: =X32*X35/60 -> 125 | M73: m3
B74: HHLL to HLL Space | J74: : | K74: =K73/K65*1000 -> 267.69845 | M74: mm | R74: taken | T74: : | U74: 268 | W74: mm | Z74: HLL to HHLL
...

Sheet T46
A2: OVERFILL STORAGE TANK SIZING
A3: FUEL TANK
B5: LOCATION | G5: : | H5: IT SURABAYA | Z5: By | AB5: :
B6: PROJECT TITLE | G6: : | H6: Tangki Timbun BBM T46 | Z6: Check | AB6: : | AI6: =PI()*H34 -> 76.548047 | AJ6: =AI6/6 -> 12.758008
H7: BIOSOLAR B40 | Z7: Rev | AB7: :
AJ9: DIMENSION
A11: A. Reference
B12: API 2350 - Overfill Prevention for Storage Tanks in Petroleum Facilities
A14: B. Terms, Definitions, & Acronyms
B15: Critical High (CH) level | H15: : | I15: The highest level in the tank that product can reach without detrimental impacts (i.e. product overflow or tank damage)
B17: High-High tank level alarm (LAHH) | H17: : | I17: An alarm generated when the product level reaches the High-High (HH) tank level
B18: High-High (HH) tank level | H18: : | I18: A level sufficiently below the Critical High (CH) level to enable termination of a receipt or transfer before the Critical High (CH) level is reached
B20: AOPS | H20: : | I20: Automated Overfill Prefention System
B21: CH | H21: : | I21: Critical High
B22: HH | H22: : | I22: High-High tank level
B23: LAHH | H23: : | I23: High-High tank level alarm
B24: FC | H24: : | I24: Foam Chamber
B25: TA | H25: : | I25: Top Angle
A27: A. Purpose
B28: To obtain level of concern storage tank at IT SURABAYA
A30: C. Summary Data
B31: Required Capacity (SAFE) | G31: : | H31: =Sheet1!B37 -> 4834 | K31: kL | R31: Calculation Data
B32: Shell plate height | G32: : | H32: 1.82 | K32: m | R32: Inlet Flow | W32: : | X32: 500 | AA32: m3/hr
C33: Diameter | G33: : | H33: =L33*6/PI() -> 9.5492966 | K33: m | L33: 5 | N33: plates (H)
B34: Diameter Taken | G34: : | H34: 24.366 | K34: m | R34: Outlet Flow | W34: : | X34: 300 | AA34: m3/hr
B35: Number of Shell | G35: : | H35: 6 | K35: plates (V) | R35: Response Time | W35: : | X35: 15 | AA35: minutes | AC35: H to HH
B36: Total Tank Height | G36: : | H36: =H32*H35 -> 10.92 | K36: m | R36: Critical High Response | W36: : | X36: 30 | AA36: minutes | AC36: HH to FC
R37: Response Time | W37: : | X37: 15 | AA37: minutes | AC37: L to LL
B39: Critcal High (CH) = Tabel Tangki Tinggi Max Vol. Bersih | L39: : | M39: =U39+U68+U74 -> 11106 | N39: mm | O39: See SAP & Tabel Tangki | U39: =Sheet1!C37 -> 10300 | X39: mm
B40: Low Level (LLLL) = Unpumpable/Dead Stock (Data SAP) | L40: : | M40: =U40/1000 -> 364 | N40: KL | O40: See Data SAP | U40: =Sheet1!M37 -> 364000 | X40: L
M41: =Sheet1!E37 -> 710 | N41: mm | O41: See SAP & Tabel Tangki
AX64: =306+(3*2.54) -> 313.62
