Workbook
Name down: INDIRECT('Analisa Barrier'!#REF!)
Name down: INDIRECT('[1]Summary Data'!#REF!)
Name down: INDIRECT('[1]Summary Data'!#REF!)
Name down: INDIRECT('[1]Summary Data'!#REF!)
Name down: INDIRECT('[1]Summary Data'!#REF!)
Name down: INDIRECT('[1]Summary Data'!#REF!)
Name down: INDIRECT('[1]Summary Data'!#REF!)
Name down: INDIRECT('[1]Summary Data'!#REF!)
Name down: INDIRECT('[1]Summary Data'!#REF!)
Name down: INDIRECT('[1]Summary Data'!#REF!)
Name down: INDIRECT('[1]Summary Data'!#REF!)
Name down: INDIRECT('[1]Summary Data'!#REF!)
Name down: INDIRECT('[1]Summary Data'!#REF!)
Name down: INDIRECT('[1]Summary Data'!#REF!)
Name down: INDIRECT('[1]Summary Data'!#REF!)
Name down: INDIRECT('[1]Summary Data'!#REF!)
Name down: INDIRECT('[1]Summary Data'!#REF!)
Name down: INDIRECT('[1]Summary Data'!#REF!)
Name down: INDIRECT('[1]Summary Data'!#REF!)
Name down: INDIRECT('[1]Summary Data'!#REF!)
Name down: INDIRECT('[1]Summary Data'!#REF!)
Name down: INDIRECT('[1]Summary Data'!#REF!)
Name down: INDIRECT('[1]Summary Data'!#REF!)
Name down: INDIRECT('[1]Summary Data'!#REF!)
Name down: INDIRECT('[1]Summary Data'!#REF!)
Name down: INDIRECT('[1]Summary Data'!#REF!)
Name down: INDIRECT('[1]Summary Data'!#REF!)
Name down: INDIRECT('[1]Summary Data'!#REF!)
Name ER01_Escape_Route___Emergency_Escape_Lighting: INDIRECT('Analisa Barrier'!#REF!)
Name ER01_Escape_Route___Emergency_Escape_Lighting: INDIRECT('[1]Summary Data'!#REF!)
Name ER01_Escape_Route___Emergency_Escape_Lighting: INDIRECT('[1]Summary Data'!#REF!)
Name ER01_Escape_Route___Emergency_Escape_Lighting: INDIRECT('[1]Summary Data'!#REF!)
Name ER01_Escape_Route___Emergency_Escape_Lighting: INDIRECT('[1]Summary Data'!#REF!)
Name ER01_Escape_Route___Emergency_Escape_Lighting: INDIRECT('[1]Summary Data'!#REF!)
Name ER01_Escape_Route___Emergency_Escape_Lighting: INDIRECT('[1]Summary Data'!#REF!)
Name ER01_Escape_Route___Emergency_Escape_Lighting: INDIRECT('[1]Summary Data'!#REF!)
Name ER01_Escape_Route___Emergency_Escape_Lighting: INDIRECT('[1]Summary Data'!#REF!)
Name ER01_Escape_Route___Emergency_Escape_Lighting: INDIRECT('[1]Summary Data'!#REF!)
Name ER01_Escape_Route___Emergency_Escape_Lighting: INDIRECT('[1]Summary Data'!#REF!)
Name ER01_Escape_Route___Emergency_Escape_Lighting: INDIRECT('[1]Summary Data'!#REF!)
Name ER01_Escape_Route___Emergency_Escape_Lighting: INDIRECT('[1]Summary Data'!#REF!)
Name ER01_Escape_Route___Emergency_Escape_Lighting: INDIRECT('[1]Summary Data'!#REF!)
Name ER01_Escape_Route___Emergency_Escape_Lighting: INDIRECT('[1]Summary Data'!#REF!)
Name ER01_Escape_Route___Emergency_Escape_Lighting: INDIRECT('[1]Summary Data'!#REF!)
Name ER01_Escape_Route___Emergency_Escape_Lighting: INDIRECT('[1]Summary Data'!#REF!)
Name ER01_Escape_Route___Emergency_Escape_Lighting: INDIRECT('[1]Summary Data'!#REF!)
Name ER01_Escape_Route___Emergency_Escape_Lighting: INDIRECT('[1]Summary Data'!#REF!)
Name ER01_Escape_Route___Emergency_Escape_Lighting: INDIRECT('[1]Summary Data'!#REF!)
Name ER01_Escape_Route___Emergency_Escape_Lighting: INDIRECT('[1]Summary Data'!#REF!)
Name ER01_Escape_Route___Emergency_Escape_Lighting: INDIRECT('[1]Summary Data'!#REF!)
Name ER01_Escape_Route___Emergency_Escape_Lighting: INDIRECT('[1]Summary Data'!#REF!)
Name ER01_Escape_Route___Emergency_Escape_Lighting: INDIRECT('[1]Summary Data'!#REF!)
Name ER01_Escape_Route___Emergency_Escape_Lighting: INDIRECT('[1]Summary Data'!#REF!)
Name ER01_Escape_Route___Emergency_Escape_Lighting: INDIRECT('[1]Summary Data'!#REF!)
Name ER01_Escape_Route___Emergency_Escape_Lighting: INDIRECT('[1]Summary Data'!#REF!)
Name ER01_Escape_Route___Emergency_Escape_Lighting: INDIRECT('[1]Summary Data'!#REF!)
Name ER03_Muster_Point: INDIRECT('Analisa Barrier'!#REF!)
Name ER03_Muster_Point: INDIRECT('[1]Summary Data'!#REF!)
Name ER03_Muster_Point: INDIRECT('[1]Summary Data'!#REF!)
Name ER03_Muster_Point: INDIRECT('[1]Summary Data'!#REF!)

Sheet Cover
C3: DOKUMEN IDENTIFIKASI SKENARIO MAJOR ACCIDENT HAZARD (MAH) & INTEGRITY SECE
C6: LOKASI | F6: : | G6: DPPU Eltari | L6: TAHUN PENYUSUNAN | Q6: : | R6: 2023
C7: REGION | F7: : | G7: V JATIMBALINUS | L7: REVISI KE- | Q7: : | R7: 0
C8: SUB HOLDING | F8: : | G8: C&T
C10: REFFERENSI
C11: 1. Pedoman No. No.A-002/CT03000/2021-S9 tentang Sistem Pengelolaan Keselamatan Proses dan Keterpaduan Aset (Process Safety & Asset Integrity Management System) Tahun 2021. 2. TKO No. No.B-001/CT03100/2021-S9 tentang Indikator Kinerja Keselamatan Proses dan Keterpaduan Aset Tahun 2021. 3. SUPREME (Sustainability Pertamina Expectations for HSSE Management Excellence) Tahun 2019, Revisi-1.
C15: SITE OVERVIEW
C16: DPPU Eltari merupakan Depot Pengisian Pesawat Udara yang menyuplai avtur atau Jet A-1 ke pesawat udara di Bandar Udara Internasional Eltari. DPPU Eltari memiliki 6 Unit Tangki Storage dengan total kapasitas sebesar 800 KL. Untuk sarana pengisian pesawat udara DPPU Eltari memiliki 6 Unit Kendaraan Refueller.
C21: SCENARIO & CAUSES FACTOR
C22: No | D22: Causes Factor | L22: RF | N22: SF | P22: DF
C23: 1 | D23: Internal/ External Corrosion
L24: √ | N24: √ | P24: √
C26: 2 | D26: Kegagalan pada Flanges, Small Bore atau Equpiment Seal
L27: √ | N27: √ | P27: √
C29: 3 | D29: Operasi diluar design operasional
L30: √ | N30: √ | P30: √
C32: 4 | D32: Aktivitas Maintenance
L33: √ | N33: √ | P33: √
C35: 5 | D35: Terdampak aktivitas kapal dan/atau Third party activities
L36: √ | N36: - | P36: √
C38: 6 | D38: Akibat Normal Operasi (termasuk Aktivitas Sampling)
L39: √ | N39: √ | P39: √
C41: 7 | D41: Kegagalan Pada supporting Structure
L42: √ | N42: √ | P42: √
C44: 8 | D44: Akibat Cuca Buruk dan/atau bencana alam
L45: √ | N45: √ | P45: √
C48: GLOSSARY
C49: - MAH : Major Accident Hazard | K49: -RF : Receiving Facility
C50: - MAE: major Accident Event | K50: - SF : Storage Facility
C51: - SECE : Safety & Environment Critical Elements | K51: - DF : Distributing Facility
C52: - PSAIMS : Process Safety & Asset Integrity Management System
C55: APPROVAL DOCUMENT
C56: Disiapkan dan Diperiksa Oleh,
C57: Sr Spv Receiving, Storage & Distribution | H57: Spv Maintenance | N57: Jr Spv HSSE & GA
C62: Audiyatra Aji Riswantarbi | H62: Musdiyanto | N62: M Iqbal Firdaus
G64: Disetujui Oleh,
G65: OH DPPU Eltari Group
G70: Agung Doddy Ferlanda

Sheet Data Vald.
A2: Data Validation for Status Barrier
A3: -
A4: N/A
A5: 0
A6: 0.25
A7: 0.5
A8: 0.75
A9: 1

Sheet RAM
B1: LAMPIRAN 2 – Matriks Penilaian Risiko
B2: TKO No B-002/CT03100/2021-S9 Revisi ke-0
D4: RISK = LIKELIHOOD X SEVERITY | M4: SKALA | N4: Manusia | P4: Environment | R4: Finansial | T4: Asset & Peralatan | V4: Reputation & Legal Impact | X4: Notifikasi Publik
B5: DAMPAK (SEVERITY) | C5: 5 Catastrophic | D5: 5 | E5: 10 | F5: 15 | G5: 20 | H5: 25 | L5: SEVERITY | M5: 5 Catastrophic | N5: · Fatalitas ganda · Menyebabkan wabah ke lingkungan · Bahan dengan potensi menyebabkan banyak kematian, mis. Bahan kimia dengan efek toksik akut | P5: • Menyebabkan kerusakan lingkungan yang sangat serius, berdampak jangka panjang terhadap fungsi ekosistem atau Tumpahan Minyak> 100 Barrel. | R5: • ≥ 80% BTR (BTR adalah nilai keuntungan perusahaan yang ditetapkan oleh fungsi keuangan di lokasi terkait) | T5: • Kehilangan total pada Pabrik/ Plant atau perkiraan biaya perbaikan >US $ 5.000.000. | V5: Dampak Luas Internasional dan Nasional : · Potensi peliputan media nasional & internasional yang mempengaruhi Anak Perusahaan & Pertamina Persero. ·Potensi tuntutan hukum oleh regulator & masyarakat yang terkena dampak. ·Kemarahan publik untuk menghentikan operasi. ·Potensi perbaikan lingkungan yang diminta oleh regulator. | X5: • Evakuasi area lengkap.
C6: 4 Significant | D6: 4 | E6: 8 | F6: 12 | G6: 16 | H6: 20 | M6: 4 Significant | N6: • Fatalitas Tunggal / Cacat Permanen / menyebabkan hilangnya hari kerja (Day Away From Works) • Bahan yang mampu menghasilkan efek serius dan tidak dapat dipulihkan sehingga menyebabkan terjadinya kematian. | P6: • Menyebabkan efek lingkungan yang serius dan berdampak jangka menengah atau Tumpahan Minyak 15 - 100 Barrel. | R6: • 60% ≤ BTR ≤ 80% | T6: • Kehilangan sebagian Pabrik. • Pabrik ditutup atau diperkirakan biaya perbaikan US $ 1.000.000 - US $ 5.000.000.. | V6: Dampak regional : ·Potensi peliputan media regional ke Anak Perusahaan & Pertamina Persero. ·Potensi tuntutan hukum oleh regulator & masyarakat yang terkena dampak. ·Potensi perbaikan lingkungan yang diminta oleh regulator. | X6: • Pemberitahuan Evakuasi terhadap area yang dipilih.
C7: 3 Moderate | D7: 3 | E7: 6 | F7: 9 | G7: 12 | H7: 15 | M7: 3 Moderate | N7: • Cacat Non Permanen / menyebabkan pembatasan aktivitas kerja (Restricted Work Cases). • Bahan yang mampu menghasilkan efek yang tidak dapat dipulihkan tanpa menyebabkan kematian tetapi terjadi kecacatan yang serius dan rawat inap yang lama. | P7: • Menyebakan efek lingkungan yang sedang dan berdampak jangka pendek tetapi tidak mempengaruhi fungsi ekosistem atau Tumpahan minyak 5-15 Barrel. | R7: • 40% ≤ BTR ≤ 60% | T7: • Sebagian instalasi mengalami kerusakan atau biaya perbaikan diperkirakan $ 100.000 - $ 1.000.000. | V7: Lokal (dampak kota) : ·Potensi paparan media lokal. ·Potensi klaim hukum oleh korban yang terkena dampak. ·Diperlukan perbaikan lingkungan yang potensial. | X7: • Pemberitahuan terhadap Shelter di lokasi.
C8: 2 Minor | D8: 2 | E8: 4 | F8: 6 | G8: 8 | H8: 10 | M8: 2 Minor | N8: •Kasus perawatan medis. • Bahan yang mampu memberikan efek kesehatan minor yang dapat dipulihkan (tidak ada rawat inap). | P8: • Menyebabkan efek minor pada lingkungan biologis atau fisik atau Tumpahan minyak 1-5 Barrel. | R8: • 20% ≤ BTR ≤ 40% | T8: • Gangguan singkat yang mungkin terjadi pada proses atau perkiraan biaya perbaikan adalah $ 10.000 - $ 100.000. | V8: Dampak internal : ·Potensi eksposur media. ·Permintaan oleh regulator. | X8: • Lokal (Pemberitahuan Telepon / selebaran).
C9: 1 Insignificant | D9: 1 | E9: 2 | F9: 3 | G9: 4 | H9: 5 | M9: 1 Insignificant | N9: •Kasus P3K. • Tidak mempengaruhi aktivitas kerja. | P9: • Menyebabkan kerusakan terbatas pada area yang minimal dengan signifikansi yang rendah atau Tumpahan Minyak <1 Barrel. | R9: • ≤ 20% BTR | T9: •Tidak ada gangguan terhadap proses atau perkiraan biaya perbaikan <$ 10.000. | V9: Tidak Ada Dampak Reputasi : ·Tidak ada perhatian media | X9: • Tidak ada komunikasi ke Publik.
B10: LEVEL | D10: 1 (Rare) | E10: 2 (Unlikely) | F10: 3 (Moderate) | G10: 4 (Likely) | H10: 5 (Almost)
D11: 0% < X < 20% | E11: 20% < X < 40% | F11: 40% < X < 60% | G11: 60% < X < 80% | H11: 80% < X < 100% | L11: LIKELIHOOD | M11: SKALA | N11: DEFINISI
D12: <10-6 per year | E12: 10-6 to 10-4 per year | F12: 10-4 to 10-2 per year | G12: 10-2 to 1 per year | H12: > 1 per year | M12: 5 | N12: Hampir Pasti Terjadi (Almost) | O12: > 1 per year | P12: Terjadi beberapa kali di wilayah operasi Pertamina ATAU terjadi beberapa kali di lokasi terkait dalam 1 tahun terakhir ATAU adanya kondisi yang memungkinkan kejadian dapat terjadi di wilayah operasi Pertamina lebih dari sekali tiap tahunnya
D13: KEMUNGKINAN (PROBABILITAS/LIKELIHOOD) | M13: 4 | N13: Sangat Mungkin Terjadi (Likely) | O13: 10-2 to 1 per year | P13: Pernah terjadi lebih dari sekali selama masa hidup operasi (operational lifetime) Pertamina ATAU pernah terjadi sekali di lokasi terkait ATAU adanya kondisi yang memungkinkan kejadian dapat terjadi lebih dari sekali di wilayah operasi Pertamina selama masa hidup operasi nya.
M14: 3 | N14: Bisa Terjadi (Moderate) | O14: 10-4 to 10-2 per year | P14: Pernah terjadi lebih dari sekali di Industri Migas / Panas Bumi / Gedung Perkantoran ATAU pernah terjadi sekali di wilayah operasi Pertamina.
M15: 2 | N15: Jarang Terjadi (Unlikely) | O15: 10-6 to 10-4 per year | P15: Pernah terjadi sekali di Industri Migas / Panas Bumi / Gedung Perkantoran.
M16: 1 | N16: Hampir Tidak Mungkin Terjadi (Rare) | O16: <10-6 per year | P16: Tidak pernah terdengar di Industry Migas / Panas Bumi / Gedung Perkantoran
B18: KRITERIA RISIKO
B19: Skor Risiko | C19: Tingkat Risiko | D19: Penerimaan Risiko dan ALARP | E19: Prioritas | F19: Tindakan Pengendalian
B20: 15-25 | C20: High (H) | D20: Unacceptable Risk | E20: 1 | F20: Serangkaian rencana mitigasi risiko harus segera dilakukan untuk mengurangi risiko dengan kondisi dan persyaratan sebagai berikut: 1) Menunda pekerjaan/proyek/operasi hingga rencana mitigasi risiko jangka panjang dilakukan dan mengurangi risiko sampai ke tingkat Medium. 2) Untuk melanjutkan pekerjaan/proyek/operasi maka penerapan dispensasi dan rencana mitigasi risiko jangka pendek harus mendapat persetujuan dari pejabat dua tingkat di atas Risk Owner, sementara rencana mitigasi jangka panjang harus tetap dipersiapkan. 3) Rencana mitigasi risiko jangka panjang dijalankan serta dilakukan monitoring secara berkala untuk memastikan keefektifan tindakan pengendalian dan penurunan tingkat risiko. 4) Untuk skenario risiko yang potensial menyebabkan multiple fatalities, maka minimal harus dilakukan analisa risiko semi quantitative.
B21: 10-12 | C21: Moderate to High (MH) | D21: Untolerable Risk | E21: 1 | F21: Serangkaian rencana mitigasi risiko harus segera dilakukan untuk mengurangi risiko dengan kondisi dan persyaratan sebagai berikut: 1) Menunda pekerjaan/proyek/operasi hingga rencana mitigasi risiko jangka panjang dilakukan dan mengurangi risiko sampai ke tingkat Medium. 2) Untuk melanjutkan pekerjaan/proyek/operasi maka penerapan dispensasi dan rencana mitigasi risiko jangka pendek harus mendapat persetujuan dari pejabat satu tingkat di atas Risk Owner, sementara rencana mitigasi jangka panjang harus tetap dipersiapkan. 3) Rencana mitigasi risiko jangka panjang dijalankan serta dilakukan monitoring secara berkala untuk memastikan keefektifan tindakan pengendalian dan penurunan tingkat risiko. 4) Untuk skenario risiko yang potensial menyebabkan multiple fatalities, maka minimal harus dilakukan analisa risiko semi quantitative.
B22: 5-9 | C22: Medium (M) | D22: Acceptable Risk | E22: 2 | F22: Mitigasi risiko jangka pendek harus dilakukan dengan persetujuan Risk Owner untuk mengelola risiko sebagai bagian dari keseluruhan program pengurangan risiko yang berkesinambungan.
B23: 4 | C23: Low to Moderate (LM) | D23: Acceptable Risk | E23: 3 | F23: Tingkat risiko yang secara umum dapat ditoleransi di mana mitigasi risiko jangka pendek harus dilakukan dengan persetujuan pejabat satu tingkat di atas PIC untuk mengelola risiko sebagai bagian dari keseluruhan program pengurangan risiko yang berkesinambungan.
B24: 1-3 | C24: Low (L) | D24: Acceptable Risk | E24: 3 | F24: Tingkat risiko yang secara umum dapat diterima di mana pengelolaan risiko secara berkesinambungan harus tertanam dan menyatu dalam seluruh kegiatan operasi untuk mencapai tujuan Perusahaan yaitu Zero Incident. Mitigasi risiko yang dibuat harus mendapat persetujuan dari pejabat satu tingkat di atas PIC.

Sheet Initial Risk
A2: Group of Equipment | B2: MAH Id. | C2: MAH Description | D2: Consequences | E2: MAH Source / Refference | F2: Risk Assessment
F3: Severity | G3: Probability | H3: Risk Number
A4: Receiving Facility DPPU Eltari | B4: MAH-RF-001 | C4: LOPC akibat peralatan mengalami internal / eksternal korosi | D4: Kebocoran produk bisa menyebabkan major spill, kebakaran dan/atau ledakan yang menyebabkan kematian personel dan/atau pencemaran lingkungan. | E4: - Dokumen MAH Tahun 2021 dan 2022 - OGB Risk Register | F4: 4 | G4: 2 | H4: =F4*G4 -> 8
B5: MAH-RF-002 | C5: LOPC akibat kegagalan/kebocoran pada valve, flange, small bore, seal | D5: Kebocoran produk bisa menyebabkan major spill, kebakaran dan/atau ledakan yang menyebabkan kematian personel dan/atau pencemaran lingkungan. | E5: - Dokumen MAH Tahun 2021 dan 2022 - OGB Risk Register | F5: 4 | G5: 2 | H5: =F5*G5 -> 8
B6: MAH-RF-003 | C6: LOPC akibat beroperasi diluar design operasional | D6: Kebocoran produk bisa menyebabkan major spill, kebakaran dan/atau ledakan yang menyebabkan kematian personel dan/atau pencemaran lingkungan. | E6: - Dokumen MAH Tahun 2021 dan 2022 - OGB Risk Register | F6: 4 | G6: 3 | H6: =F6*G6 -> 12
B7: MAH-RF-004 | C7: LOPC akibat kegiatan maintenance | D7: Kebocoran produk bisa menyebabkan major spill, kebakaran dan/atau ledakan yang menyebabkan kematian personel dan/atau pencemaran lingkungan. | E7: - Dokumen MAH Tahun 2021 dan 2022 - OGB Risk Register | F7: 4 | G7: 3 | H7: =F7*G7 -> 12
B8: MAH-RF-005 | C8: LOPC akibat terdamak aktivitas kapal dan third party activity. | D8: Kebocoran produk bisa menyebabkan major spill, kebakaran dan/atau ledakan yang menyebabkan kematian personel dan/atau pencemaran lingkungan. | E8: - Dokumen MAH Tahun 2021 dan 2022 - OGB Risk Register | F8: 4 | G8: 3 | H8: =F8*G8 -> 12
B9: MAH-RF-006 | C9: LOPC akibat Normal Operasi (termasuk aktivitas Sampling) | D9: Kebocoran produk bisa menyebabkan major spill, kebakaran dan/atau ledakan yang menyebabkan kematian personel dan/atau pencemaran lingkungan. | E9: - Dokumen MAH Tahun 2021 dan 2022 - OGB Risk Register | F9: 4 | G9: 2 | H9: =F9*G9 -> 8
B10: MAH-RF-007 | C10: LOPC akibat kegagalan supporting Structure | D10: Kebocoran produk bisa menyebabkan major spill, kebakaran dan/atau ledakan yang menyebabkan kematian personel dan/atau pencemaran lingkungan. | E10: - Dokumen MAH Tahun 2021 dan 2022 - OGB Risk Register | F10: 2 | G10: 2 | H10: =F10*G10 -> 4
B11: MAH-RF-008 | C11: LOPC akibat dampakdari cuaca buruk (angin kencang, badai, gempa bumi) | D11: Kebocoran produk bisa menyebabkan major spill, kebakaran dan/atau ledakan yang menyebabkan kematian personel dan/atau pencemaran lingkungan. | E11: - Dokumen MAH Tahun 2021 dan 2022 - OGB Risk Register | F11: 3 | G11: 3 | H11: =F11*G11 -> 9
A12: Storage Facility at DPPU Eltari | B12: MAH-SF-001 | C12: LOPC akibat peralatan mengalami internal / eksternal korosi | D12: Kebocoran produk bisa menyebabkan major spill, kebakaran dan/atau ledakan yang menyebabkan kematian personel dan/atau pencemaran lingkungan. | E12: - Dokumen MAH Tahun 2021 dan 2022 - OGB Risk Register | F12: 3 | G12: 2 | H12: =F12*G12 -> 6
B13: MAH-SF-002 | C13: LOPC akibat kegagalan/kebocoran pada valve, flange, small bore, seal | D13: Kebocoran produk bisa menyebabkan major spill, kebakaran dan/atau ledakan yang menyebabkan kematian personel dan/atau pencemaran lingkungan. | E13: - Dokumen MAH Tahun 2021 dan 2022 - OGB Risk Register | F13: 4 | G13: 3 | H13: =F13*G13 -> 12
B14: MAH-SF-003 | C14: LOPC akibat beroperasi diluar design operasional | D14: Kebocoran produk bisa menyebabkan major spill, kebakaran dan/atau ledakan yang menyebabkan kematian personel dan/atau pencemaran lingkungan. | E14: - Dokumen MAH Tahun 2021 dan 2022 - OGB Risk Register | F14: 4 | G14: 3 | H14: =F14*G14 -> 12
B15: MAH-SF-004 | C15: LOPC akibat kegiatan maintenance | D15: Kebocoran produk bisa menyebabkan major spill, kebakaran dan/atau ledakan yang menyebabkan kematian personel dan/atau pencemaran lingkungan. | E15: - Dokumen MAH Tahun 2021 dan 2022 - OGB Risk Register | F15: 4 | G15: 3 | H15: =F15*G15 -> 12
B16: MAH-SF-005 | C16: LOPC akibat aktivitas operasi normal (loading-unloading,termasuk aktivitas sampling) | D16: Kebocoran produk bisa menyebabkan major spill, kebakaran dan/atau ledakan yang menyebabkan kematian personel dan/atau pencemaran lingkungan. | E16: - Dokumen MAH Tahun 2021 dan 2022 - OGB Risk Register | F16: 4 | G16: 3 | H16: =F16*G16 -> 12
B17: MAH-SF-006 | C17: LOPC akibat kegagalan pada pondasi / base plate metal tangki | D17: Kebocoran produk bisa menyebabkan major spill, kebakaran dan/atau ledakan yang menyebabkan kematian personel dan/atau pencemaran lingkungan. | E17: - Dokumen MAH Tahun 2021 dan 2022 - OGB Risk Register | F17: 4 | G17: 3 | H17: =F17*G17 -> 12
B18: MAH-SF-007 | C18: LOPC akibat Extreem Wheather (Lightning Strike, Earthquake, Windstrom) | D18: Kebocoran produk bisa menyebabkan major spill, kebakaran dan/atau ledakan yang menyebabkan kematian personel dan/atau pencemaran lingkungan. | E18: - Dokumen MAH Tahun 2021 dan 2022 - OGB Risk Register | F18: 4 | G18: 3 | H18: =F18*G18 -> 12
A19: Distributing Facility DPPU Eltari | B19: MAH-DF-001 | C19: LOPC akibat peralatan mengalami internal / eksternal korosi | D19: Kebocoran produk bisa menyebabkan major spill, kebakaran dan/atau ledakan yang menyebabkan kematian personel dan/atau pencemaran lingkungan. | E19: - Dokumen MAH Tahun 2021 dan 2022 - OGB Risk Register | F19: 4 | G19: 3 | H19: =F19*G19 -> 12
B20: MAH-DF-002 | C20: LOPC akibat kegagalan/kebocoran pada valve, flange, small bore, seal | D20: Kebocoran produk bisa menyebabkan major spill, kebakaran dan/atau ledakan yang menyebabkan kematian personel dan/atau pencemaran lingkungan. | E20: - Dokumen MAH Tahun 2021 dan 2022 - OGB Risk Register | F20: 4 | G20: 3 | H20: =F20*G20 -> 12
B21: MAH-DF-003 | C21: LOPC akibat beroperasi diluar design operasional | D21: Kebocoran produk bisa menyebabkan major spill, kebakaran dan/atau ledakan yang menyebabkan kematian personel dan/atau pencemaran lingkungan. | E21: - Dokumen MAH Tahun 2021 dan 2022 - OGB Risk Register | F21: 4 | G21: 2 | H21: =F21*G21 -> 8
B22: MAH-DF-004 | C22: LOPC akibat kegiatan maintenance | D22: Kebocoran produk bisa menyebabkan major spill, kebakaran dan/atau ledakan yang menyebabkan kematian personel dan/atau pencemaran lingkungan. | E22: - Dokumen MAH Tahun 2021 dan 2022 - OGB Risk Register | F22: 4 | G22: 3 | H22: =F22*G22 -> 12
B23: MAH-DF-005 | C23: LOPC akibat eksternal/vehicle impact, third party activity. | D23: Kebocoran produk bisa menyebabkan major spill, kebakaran dan/atau ledakan yang menyebabkan kematian personel dan/atau pencemaran lingkungan. | E23: - Dokumen MAH Tahun 2021 dan 2022 - OGB Risk Register | F23: 4 | G23: 2 | H23: =F23*G23 -> 8
B24: MAH-DF-006 | C24: LOPC akibat aktivitas operasi normal (loading-unloading, aktivitas sampling) | D24: Kebocoran produk bisa menyebabkan major spill, kebakaran dan/atau ledakan yang menyebabkan kematian personel dan/atau pencemaran lingkungan. | E24: - Dokumen MAH Tahun 2021 dan 2022 - OGB Risk Register | F24: 4 | G24: 2 | H24: =F24*G24 -> 8
B25: MAH-DF-007 | C25: LOPC akibat kegagalan pada supporting structure | D25: Kebocoran produk bisa menyebabkan major spill, kebakaran dan/atau ledakan yang menyebabkan kematian personel dan/atau pencemaran lingkungan. | E25: - Dokumen MAH Tahun 2021 dan 2022 - OGB Risk Register | F25: 4 | G25: 2 | H25: =F25*G25 -> 8
B26: MAH-DF-008 | C26: LOPC akibat Cuaca Buruk (Gempa, Gelombang Tinggi, Badai) | D26: Kebocoran produk bisa menyebabkan major spill, kebakaran dan/atau ledakan yang menyebabkan kematian personel dan/atau pencemaran lingkungan. | E26: - Dokumen MAH Tahun 2021 dan 2022 - OGB Risk Register | F26: 4 | G26: 3 | H26: =F26*G26 -> 12

Sheet RF-01
C2: HYDROCARBON RECEIVING FACILITY
C4: MAJOR ACCIDENT HAZARD
C5: Internal / Eksternal Corrosion
C6: RECEIVING FACILITY & PROCESS OVERVIEW | G6: MAH REGISTER NO. | H6: DATE:
C7: Produk avtur DPPU Eltari diterima dari FT Tenau dengan jarak tempuh 19,8 Km atau + 29 Menit dengan Total Armada Bridger 3 Unit. DPPU ELtari memiliki 1 fasilitas filling shed penerimaan dan didukung oleh 1 pompa discharge kapasitas 300 Gpm. Produk avtur diterima di filling shed lalu dipompakan menuju ke tangki penerimaan dengan melewati FWS Terlebih dahulu. Rata-rata penerimaan 128 KL/Hari | G7: MAH-RF-001-DPPU Eltari | H7: 1 Maret 2023
G8: REFFERENCE DOC. : | H8: MAH Description :
G9: MAH Tahun 2022 | H9: Hydrocarbon release due to receiving facility corrosion (internal and/or eksternal). The release of HC resulting major spill, fire and/or explosion, it leading to serious injury and/or multiple fatalities and environment damage.
C13: PREVENTIVE MEASURES | G13: DETECTION/CONTROL MEASURES
C14: HARDWARE (PLANT)
C15: Barrier | D15: Related to MAE | E15: Status | F15: Detail / Remarks | G15: Barrier | H15: Related to MAE | I15: Status | J15: Detail / Remarks
C16: Pipeline Specification (Design Material Selection) | D16: A,B | E16: 1 | F16: API 5L Grade B Schedule 80 Dia. 4" | G16: CCTV | H16: A,B | I16: 1 | J16: Terpasang CCTV Mengarah ke Area Penerimaan
C17: Product Pump Specification (Design Material Selection) | D17: A,B | E17: 0.75 | F17: Centrifugal Diesel Pump | G17: - | H17: - | I17: - | J17: -
C18: Pipeline Specification (Internal/ External Coating) | D18: A,B | E18: 1 | F18: Internal Coating EI 1541. >=350 mikron | G18: - | H18: - | I18: - | J18: -
C19: Pipeline Specification (Cathodic Protection) | D19: A,B | E19: N/A | F19: tidak cathodic protection. | G19: - | H19: - | I19: - | J19: -
C20: Pipeline (Corrosion Inhibitor) | D20: A,B | E20: N/A | F20: tidak terpasang corrosion inhibitor ( Semua Pipa above ground) | G20: - | H20: - | I20: - | J20: -
C21: PEOPLE + PROCESS
C22: Barrier | D22: Related to MAE | E22: Status | F22: Detail / Remarks | G22: Barrier | H22: Related to MAE | I22: Status | J22: Detail / Remarks
C23: Program Periodically Inspection | D23: A,B | E23: 1 | F23: Disikan apakah ada program rutin dan periodik inspeksi. Jika diwajibkan ada dokumen COI, pastikan tersedia dokumen COI yang masih berlaku. | G23: Pipeline Leak Detection | H23: A,B | I23: 1 | J23: Visual Check Jalur Pipa
C24: Program Integrity Management / Risk Based Inspection Program (RBI) | D24: A,B | E24: 1 | F24: Dilakukan inspeksi pipeline oleh RPD | G24: Plant / Pipeline Patrol | H24: A,B | I24: 1 | J24: Pemeriksaan Rutin oleh operator Maintenance dan Security secara periodik
C25: Pipeline Pigging Programme | D25: A,B | E25: N/A | F25: Belum pernah dilakukan | G25: - | H25: - | I25: - | J25: -
C26: Programme Condition Monitoring (for rotating Equipment) / LTSA | D26: A,B | E26: N/A | F26: Tidak ada program LTSA Pompa | G26: - | H26: - | I26: - | J26: -
C27: Housekeeping Programme | D27: A,B | E27: 1 | F27: Housekeeping Program | G27: - | H27: - | I27: - | J27: -
C28: Additional Notes / Concern matter :
C29: (Diisikan jika ada catatan tambahan / informasi penting lainnya terkait assessment preventive & Detect-control barrier yang perlu dijadikan tambahan informasi).
C33: INITIATING EVENT
C35: Hydrocarbon Release / LOPC
C37: MITIGATION MEASURES | G37: EMERGENCY RESPONSE RESOURCES
C38: =C14 -> HARDWARE (PLANT)
C39: Barrier | D39: Related to MAE | E39: Status | F39: Detail / Remarks | G39: Barrier | H39: Related to MAE | I39: Status | J39: Detail / Remarks
C40: Emergency Leak Plug / Emergency Leak control equipment | D40: A | E40: 1 | F40: Tersedia peralatan penanggulangan kebocoran pipa (temporary repair), seperti Clamp, Belzona, resin, peralatan pendukung lainnya. | G40: Emergency Communication (Radio HT) | H40: A,B | I40: 1 | J40: Tersedia Radio Komunikasi / HT sesuai dengan kebutuhan (Jumlah dan spec.) dan berfungsi dengan baik.
C41: Stardarized Electrical System | D41: A | E41: 1 | F41: Listrik di area Penerimaan yang masuk hazardous area sudah sesuai spesifikasi | G41: Emergency Alarm (Beacon) | H41: A,B | I41: 1 | J41: Tersedia Alarm / lonceng di berbagai titik sebagai emergency Alarm.
C42: Shutdown Valve (SDV) | D42: A | E42: N/A | F42: Tidak terdapat SDV | G42: Muster Point | H42: A,B | I42: 1 | J42: Tersedia area Muster Point ( rambu dan penunjuk jalur tersedia, visible), jarak cukup jauh dengan sumber api > 100 m,.
C43: Portable Gas Detector | D43: A | E43: 1 | F43: Tersedia Portable Gas Detector. | G43: APD/PPE untuk tumpahan bahan bakar (safety boot, wearpack, masker catridge) | H43: A | I43: 0.75 | J43: Tersedia safety boot, wearpack dan masker catridge sesuai dengan kebutuhan untuk penanggulangan tumpahan / kebocoran produk.(Belum memliki Baju Fire Fighting)
C44: Fixed Fire & Gas Detector System (FGDS) | D44: A,B | E44: N/A | F44: Tidak Terpasang Fixed FGDS di area penerimaan. | G44: Oil Spill Emergency Repsonse (Oil Boom,oil absorbent, skimmer, dll) | H44: A | I44: 1 | J44: Tersedia pealatan penaggulang tumpahan minyak.
C45: Lightning Protection System | D45: B | E45: 1 | F45: Apakah terpasang LPS di area pendistribution dengan jumlah, coverage dan program monitoring yang cukup. | G45: Fixed Fire Fighting Equipment/System (Fire Pump, Fire Hydran, Fire Water Line). | H45: B | I45: 1 | J45: Tersedia peralatan penanggulangan kebakaran, termasuk Fire Risk Card sesuai skenario.
C46: Grounding System | D46: B | E46: 1 | F46: Grounding System | G46: Mobile emergency Response Eqipment (Fire Truck, Fire Jeep,QRU, LPG Evacuation Unit, Vacuum Truck) | H46: A,B | I46: N/A | J46: Tidak tersedia Mobile Equipment Response dan kondisi nya
C47: Oil Catcher System | D47: A | E47: 1 | F47: Tersedia oil cathcer yang sesuai persyaratan dan spesifikasi. | G47: Generator Set (Genset) untuk Power Supply saat Emergency | H47: B | I47: 1 | J47: Ttersedia unit Genset yang siap pakai dan COI nya valid
C48: =C21 -> PEOPLE + PROCESS
C49: Barrier | D49: Related to MAE | E49: Status | F49: Detail / Remarks | G49: Barrier | H49: Related to MAE | I49: Status | J49: Detail / Remarks
C50: Electrical Hazardous Area Classification (EHAC) | D50: A,B | E50: 1 | F50: Pengklasifikasiaan peralatan dan electrical system sesuai hazardous area sudah diterapkan. | G50: Organisasi & Personel Pengendalian Tanggap Darurat yang Kompeten | H50: A,B | I50: 1 | J50: Sudah ditetapkan Organisasi dan Personel Pengendalian Keadaan Darurat setempat.
...

Sheet RF-02
C2: HYDROCARBON RECEIVING FACILITY
C4: MAJOR ACCIDENT HAZARD
C5: Failure at Valve, Flange, Seal & Small Bore
C6: RECEIVING FACILITY & PROCESS OVERVIEW | G6: MAH REGISTER NO. | H6: DATE:
C7: Produk avtur DPPU Eltari diterima dari FT Tenau dengan jarak tempuh 19,8 Km atau + 29 Menit dengan Total Armada Bridger 3 Unit. DPPU ELtari memiliki 1 fasilitas filling shed penerimaan dan didukung oleh 1 pompa discharge kapasitas 300 Gpm. Produk avtur diterima di filling shed lalu dipompakan menuju ke tangki penerimaan dengan melewati FWS Terlebih dahulu. Rata-rata penerimaan 128 KL/Hari | G7: MAH-RF-002-DPPU Eltari | H7: 1 Maret 2023
G8: REFFERENCE DOC. : | H8: MAH Description :
G9: MAH Tahun 2022 | H9: Hydrocarbon release due to failure or broke valve, flange, seal & small-bore . The release of HC resulting major spill, fire and/or explosion, it leading to serious injury and/or multiple fatalities and environment damage.
C13: PREVENTIVE MEASURES | G13: DETECTION/CONTROL MEASURES
C14: HARDWARE (PLANT)
C15: Barrier | D15: Related to MAE | E15: Status | F15: Detail / Remarks | G15: Barrier | H15: Related to MAE | I15: Status | J15: Detail / Remarks
C16: Pipeline Specification (Design Material Selection) | D16: A,B | E16: 1 | F16: API 5L Grade B Schedule 80 Dia. 4" | G16: CCTV | H16: A,B | I16: 1 | J16: Diisikan apakah terpasang CCTV di area penerimaan.
C17: Product Pump Specification (Design Material Selection) | D17: A,B | E17: 1 | F17: Centrifugal Diesel Pump | G17: - | H17: - | I17: - | J17: -
C18: Standarized Bolting Practices | D18: A,B | E18: 1 | F18: Diisikan jika sudah ada standar atau ketentuan terkait dengan pengencangan Mur Baut (Bolting) menggunakan Kunci Torsi | G18: - | H18: - | I18: - | J18: -
C19: PEOPLE + PROCESS
C20: Barrier | D20: Related to MAE | E20: Status | F20: Detail / Remarks | G20: Barrier | H20: Related to MAE | I20: Status | J20: Detail / Remarks
C21: Program Periodically Inspection | D21: A,B | E21: 1 | F21: Disikan apakah ada program rutin dan periodik inspeksi. Jika diwajibkan ada dokumen COI, pastikan tersedia dokumen COI yang masih berlaku. | G21: Pipeline Leak Detection | H21: A,B | I21: 1 | J21: Visual Check Jalur Pipa
C22: Program Integrity Management / Risk Based Inspection Program (RBI) | D22: A,B | E22: N/A | F22: Diisikan apakah program RBI asudah berjalan di lokasi | G22: Plant / Pipeline Patrol | H22: A,B | I22: 1 | J22: Pemeriksaan Rutin oleh operator Maintenance dan Security secara periodik
C23: Pemeliharaan & Pergantian Valve/Flange/Gasket secara periodikal | D23: A,B | E23: 1 | F23: ada program permeriksaan / pergantian connection / flange / gasket secara periodik. | G23: Program analysis fugitive realease menggunakan fugitive imaging camera | H23: A | I23: N/A | J23: Apakah program analysis fugitive release sudah dilaksanakan secara rutin.
C24: Programme Condition Monitoring (for rotating Equipment) / LTSA | D24: A,B | E24: N/A | F24: Belum ada LTSA Pompa | G24: - | H24: - | I24: - | J24: -
C25: Housekeeping Programme | D25: A,B | E25: 1 | F25: Housekeeping Programme | G25: - | H25: - | I25: - | J25: -
C26: Additional Notes / Concern matter :
C27: (Diisikan jika ada catatan tambahan / informasi penting lainnya terkait assessment preventive & Detect-control barrier yang perlu dijadikan tambahan informasi).
C31: INITIATING EVENT
C33: Hydrocarbon Release / LOPC
C35: MITIGATION MEASURES | G35: EMERGENCY RESPONSE RESOURCES
C36: =C14 -> HARDWARE (PLANT)
C37: Barrier | D37: Related to MAE | E37: Status | F37: Detail / Remarks | G37: Barrier | H37: Related to MAE | I37: Status | J37: Detail / Remarks
C38: Emergency Leak Plug / Emergency Leak control equipment | D38: A | E38: 1 | F38: Tersedia peralatan penanggulangan kebocoran pipa (temporary repair), seperti Clamp, Belzona, resin, peralatan pendukung lainnya. | G38: Emergency Communication (Radio HT) | H38: A,B | I38: 1 | J38: Tersedia Radio Komunikasi / HT sesuai dengan kebutuhan (Jumlah dan spec.) dan berfungsi dengan baik.
C39: Stardarized Electrical System | D39: A | E39: 1 | F39: Listrik di area Penerimaan yang masuk hazardous area sudah sesuai spesifikasi | G39: Emergency Alarm (Beacon) | H39: A,B | I39: 1 | J39: Tersedia Alarm / lonceng di berbagai titik sebagai emergency Alarm.
C40: Shutdown Valve (SDV) | D40: A | E40: N/A | F40: Tidak terdapat SDV | G40: Muster Point | H40: A,B | I40: 1 | J40: Tersedia area Muster Point ( rambu dan penunjuk jalur tersedia, visible), jarak cukup jauh dengan sumber api > 100 m,.
C41: Portable Gas Detector | D41: A | E41: 1 | F41: Tersedia Portable Gas Detector. | G41: APD/PPE untuk tumpahan bahan bakar (safety boot, wearpack, masker catridge) | H41: A | I41: 0.75 | J41: Tersedia safety boot, wearpack dan masker catridge sesuai dengan kebutuhan untuk penanggulangan tumpahan / kebocoran produk.(Belum memliki Baju Fire Fighting)
C42: Fixed Fire & Gas Detector System (FGDS) | D42: A,B | E42: N/A | F42: Tidak Terpasang Fixed FGDS di area penerimaan. | G42: Oil Spill Emergency Repsonse (Oil Boom,oil absorbent, skimmer, dll) | H42: A | I42: 1 | J42: Tersedia pealatan penaggulang tumpahan minyak.
C43: Lightning Protection System | D43: B | E43: 1 | F43: Apakah terpasang LPS di area pendistribution dengan jumlah, coverage dan program monitoring yang cukup. | G43: Fixed Fire Fighting Equipment/System (Fire Pump, Fire Hydran, Fire Water Line). | H43: B | I43: 1 | J43: Tersedia peralatan penanggulangan kebakaran, termasuk Fire Risk Card sesuai skenario.
C44: Grounding System | D44: B | E44: 1 | F44: Hasil Grounding System tercata pada form SF 211 | G44: Mobile emergency Response Eqipment (Fire Truck, Fire Jeep,QRU, LPG Evacuation Unit, Vacuum Truck) | H44: A,B | I44: N/A | J44: Tidak tersedia Mobile Equipment Response dan kondisi nya
C45: Oil Catcher System | D45: A | E45: 1 | F45: Tersedia oil cathcer yang sesuai persyaratan dan spesifikasi. | G45: Generator Set (Genset) untuk Power Supply saat Emergency | H45: B | I45: 1 | J45: Ttersedia unit Genset yang siap pakai dan COI nya valid
C46: =C19 -> PEOPLE + PROCESS
C47: Barrier | D47: Related to MAE | E47: Status | F47: Detail / Remarks | G47: Barrier | H47: Related to MAE | I47: Status | J47: Detail / Remarks
C48: Electrical Hazardous Area Classification (EHAC) | D48: A,B | E48: 1 | F48: Pengklasifikasiaan peralatan dan electrical system sesuai hazardous area sudah diterapkan. | G48: Organisasi & Personel Pengendalian Tanggap Darurat yang Kompeten | H48: A,B | I48: 1 | J48: Sudah ditetapkan Organisasi dan Personel Pengendalian Keadaan Darurat setempat.
C49: Security Guard | D49: A,B | E49: 1 | F49: Tersedia personel dan aktivitas pengamanan saat di area penerimaan. | G49: Pedoman Pengendalian Keadaan Darurat | H49: A | I49: 1 | J49: Tersedia Pedoman Pengendalian Keadaan Darurat (PKD) terbaru.
C50: Pipeline ROW (signage, clearence, maintenace). | D50: A,B | E50: 1 | F50: Apakah Pipeline ROW (Righ-of-ways) sudah ditetapkan, diberitanda, dibersihkan dan dilakukan pemeliharaan. | G50: Bussiness Continuity Plan/Management | H50: A,B | I50: 1 | J50: Tersedia dokumen BCP / Skenario RAE.
...

Sheet RF-03
C2: HYDROCARBON RECEIVING FACILITY
C4: MAJOR ACCIDENT HAZARD
C5: Operating Outside of Designated Operational Envelope
C6: RECEIVING FACILITY & PROCESS OVERVIEW | G6: MAH REGISTER NO. | H6: DATE:
C7: Produk avtur DPPU Eltari diterima dari FT Tenau dengan jarak tempuh 19,8 Km atau + 29 Menit dengan Total Armada Bridger 3 Unit. DPPU ELtari memiliki 1 fasilitas filling shed penerimaan dan didukung oleh 1 pompa discharge kapasitas 300 Gpm. Produk avtur diterima di filling shed lalu dipompakan menuju ke tangki penerimaan dengan melewati FWS Terlebih dahulu. Rata-rata penerimaan 128 KL/Hari | G7: MAH-RF-003-Eltari | H7: 1 Maret 2023
G8: REFFERENCE DOC. : | H8: MAH Description :
G9: MAH Tahun 2022 | H9: Hydrocarbon release due to Operating Outside of Design Operational Envelope / SOL envelope. The release of HC resulting major spill, fire and/or explosion, it leading to serious injury and/or multiple fatalities and environment damage.
C13: PREVENTIVE MEASURES | G13: DETECTION/CONTROL MEASURES
C14: HARDWARE (PLANT)
C15: Barrier | D15: Related to MAE | E15: Status | F15: Detail / Remarks | G15: Barrier | H15: Related to MAE | I15: Status | J15: Detail / Remarks
C16: Pipeline Specification (Design Material Selection) | D16: A,B | E16: 1 | F16: API 5L Grade B Schedule 80 Dia. 4" | G16: CCTV | H16: A,B | I16: 1 | J16: terpasang CCTV di area penerimaan.
C17: Product Pump Specification (Design Material Selection) | D17: A,B | E17: 1 | F17: Centrifugal Diesel Pump | G17: Mechanical overpresure protection (PSV di jalur penerimaan). | H17: A,B | I17: N/A | J17: tidak ada PCV di Area Penerimaan
C18: - | D18: - | E18: - | F18: - | G18: Safety Instrumented function (PAHH dan PALL pada Pompa) | H18: A,B | I18: 1 | J18: Diesel Pump dilengkapi ESD
C19: - | D19: - | E19: - | F19: - | G19: Actuated Isolation valve (MOV) | H19: A | I19: N/A | J19: Tidak Terpasang MOV di jalur penerimaan, termasuk supply listrik untuk menggerakan MOV.
C20: PEOPLE + PROCESS
C21: Barrier | D21: Related to MAE | E21: Status | F21: Detail / Remarks | G21: Barrier | H21: Related to MAE | I21: Status | J21: Detail / Remarks
C22: Program Periodically Inspection | D22: A,B | E22: 1 | F22: Disikan apakah ada program rutin dan periodik inspeksi. Jika diwajibkan ada dokumen COI, pastikan tersedia dokumen COI yang masih berlaku. | G22: Pipeline Leak Detection | H22: A,B | I22: N/A | J22: apakah ada sistem / prosedur / metoda / peralatan untuk mendetaksi kebocoran sepanjang jalur pipa?
C23: Program Integrity Management / Risk Based Inspection Program (RBI) | D23: A,B | E23: N/A | F23: Diisikan apakah program RBI asudah berjalan di lokasi | G23: Plant / Pipeline Patrol | H23: A,B | I23: 1 | J23: Security memiliki program patrol
C24: Prosedur Penerimaan Produk | D24: A,B | E24: 1 | F24: Pompav Buku 2 Pengendalian Mutu BBMP | G24: - | H24: - | I24: - | J24: -
C25: Programme Condition Monitoring (for rotating Equipment) / LTSA | D25: A,B | E25: N/A | F25: Belum ada LTSA Pompa | G25: - | H25: - | I25: - | J25: -
C26: Housekeeping Programme | D26: A,B | E26: 1 | F26: Housekeeping Programme | G26: - | H26: - | I26: - | J26: -
C27: Additional Notes / Concern matter :
C28: (Diisikan jika ada catatan tambahan / informasi penting lainnya terkait assessment preventive & Detect-control barrier yang perlu dijadikan tambahan informasi).
C32: INITIATING EVENT
C34: Hydrocarbon Release / LOPC
C36: MITIGATION MEASURES | G36: EMERGENCY RESPONSE RESOURCES
C37: =C14 -> HARDWARE (PLANT)
C38: Barrier | D38: Related to MAE | E38: Status | F38: Detail / Remarks | G38: Barrier | H38: Related to MAE | I38: Status | J38: Detail / Remarks
C39: Emergency Leak Plug / Emergency Leak control equipment | D39: A | E39: 1 | F39: Tersedia peralatan penanggulangan kebocoran pipa (temporary repair), seperti Clamp, Belzona, resin, peralatan pendukung lainnya. | G39: Emergency Communication (Radio HT) | H39: A,B | I39: 1 | J39: Tersedia Radio Komunikasi / HT sejumlah …
C40: Stardarized Electrical System | D40: A | E40: 1 | F40: Listrik di area Penerimaan yang masuk hazardous area sudah sesuai spesifikasi | G40: Emergency Alarm (Beacon) | H40: A,B | I40: 1 | J40: Tersedia Alarm / lonceng di berbagai titik sebagai emergency Alarm.
C41: Shutdown Valve (SDV) | D41: A | E41: N/A | F41: Tidak terdapat SDV | G41: Muster Point | H41: A,B | I41: 1 | J41: Tersedia area Muster Point ( rambu dan penunjuk jalur tersedia, visible), jarak cukup jauh dengan sumber api > 100 m,.
C42: Portable Gas Detector | D42: A | E42: 1 | F42: Tersedia Portable Gas Detector. | G42: APD/PPE untuk tumpahan bahan bakar (safety boot, wearpack, masker catridge) | H42: A | I42: 0.75 | J42: Tersedia safety boot, wearpack dan masker catridge sesuai dengan kebutuhan untuk penanggulangan tumpahan / kebocoran produk.(Belum memliki Baju Fire Fighting)
C43: Fixed Fire & Gas Detector System (FGDS) | D43: A,B | E43: N/A | F43: Tidak Terpasang Fixed FGDS di area penerimaan. | G43: Oil Spill Emergency Repsonse (Oil Boom,oil absorbent, skimmer, dll) | H43: A | I43: 1 | J43: Tersedia pealatan penaggulang tumpahan minyak.
C44: Lightning Protection System | D44: B | E44: 1 | F44: Apakah terpasang LPS di area pendistribution dengan jumlah, coverage dan program monitoring yang cukup. | G44: Fixed Fire Fighting Equipment/System (Fire Pump, Fire Hydran, Fire Water Line). | H44: B | I44: 1 | J44: Tersedia peralatan penanggulangan kebakaran, termasuk Fire Risk Card sesuai skenario.
C45: Grounding System | D45: B | E45: 1 | F45: Hasil Grounding System tercata pada form SF 211 | G45: Mobile emergency Response Eqipment (Fire Truck, Fire Jeep,QRU, LPG Evacuation Unit, Vacuum Truck) | H45: A,B | I45: N/A | J45: Tidak tersedia Mobile Equipment Response dan kondisi nya
C46: Oil Catcher System | D46: A | E46: 1 | F46: Tersedia oil cathcer yang sesuai persyaratan dan spesifikasi. | G46: Generator Set (Genset) untuk Power Supply saat Emergency | H46: B | I46: 1 | J46: Ttersedia unit Genset yang siap pakai dan COI nya valid
C47: =C20 -> PEOPLE + PROCESS
C48: Barrier | D48: Related to MAE | E48: Status | F48: Detail / Remarks | G48: Barrier | H48: Related to MAE | I48: Status | J48: Detail / Remarks
C49: Electrical Hazardous Area Classification (EHAC) | D49: A,B | E49: 1 | F49: Pengklasifikasiaan peralatan dan electrical system sesuai hazardous area sudah diterapkan. | G49: Organisasi & Personel Pengendalian Tanggap Darurat yang Kompeten | H49: A,B | I49: 1 | J49: Sudah ditetapkan Organisasi dan Personel Pengendalian Keadaan Darurat setempat.
C50: Security Guard | D50: A,B | E50: 1 | F50: Tersedia personel dan aktivitas pengamanan saat di area penerimaan. | G50: Pedoman Pengendalian Keadaan Darurat | H50: A | I50: 1 | J50: Tersedia Pedoman Pengendalian Keadaan Darurat (PKD) terbaru.
...

Sheet RF-04
C2: HYDROCARBON RECEIVING FACILITY
C4: MAJOR ACCIDENT HAZARD
C5: Maintenance Activity
C6: RECEIVING FACILITY & PROCESS OVERVIEW | G6: MAH REGISTER NO. | H6: DATE:
C7: Produk avtur DPPU Eltari diterima dari FT Tenau dengan jarak tempuh 19,8 Km atau + 29 Menit dengan Total Armada Bridger 3 Unit. DPPU ELtari memiliki 1 fasilitas filling shed penerimaan dan didukung oleh 1 pompa discharge kapasitas 300 Gpm. Produk avtur diterima di filling shed lalu dipompakan menuju ke tangki penerimaan dengan melewati FWS Terlebih dahulu. Rata-rata penerimaan 128 KL/Hari | G7: MAH-RF-004-Eltari | H7: 1 Maret 2023
G8: REFFERENCE DOC. : | H8: MAH Description :
G9: MAH Tahun 2022 | H9: Hydrocarbon release due to Maintenance Activites. The release of HC resulting major spill, fire and/or explosion, it leading to serious injury and/or multiple fatalities and environment damage.
C13: PREVENTIVE MEASURES | G13: DETECTION/CONTROL MEASURES
C14: HARDWARE (PLANT)
C15: Barrier | D15: Related to MAE | E15: Status | F15: Detail / Remarks | G15: Barrier | H15: Related to MAE | I15: Status | J15: Detail / Remarks
C16: - | D16: - | E16: - | F16: - | G16: CCTV | H16: A,B | I16: 0.5 | J16: CCTV terpasang di 8 Titik dan 4 titik tidak berfungsi
C17: - | D17: - | E17: - | F17: - | G17: - | H17: - | I17: - | J17: -
C18: PEOPLE + PROCESS
C19: Barrier | D19: Related to MAE | E19: Status | F19: Detail / Remarks | G19: Barrier | H19: Related to MAE | I19: Status | J19: Detail / Remarks
C20: Prosedur Perbaikan / Pemeliharaan Peralatan | D20: A,B | E20: 1 | F20: Pompav Buku 4 Pemeliharaan Sarana dan Fasilitas | G20: Plant / Pipeline Patrol | H20: A,B | I20: 1 | J20: Security secara berkala melakukan patroli jalur pipa
C21: Prosedur Sistem Ijin Kerja Aman (SIKA) | D21: A,B | E21: 1 | F21: tersedia dan dilaksanakan Prosedur SIKA. | G21: - | H21: - | I21: - | J21: -
C22: Prosedur Management of Change (MOC) | D22: A,B | E22: 1 | F22: tersedia dan dilaksanakan Prosedur MOC. | G22: - | H22: - | I22: - | J22: -
C23: Prosedur Isolation Energi (LOTO) | D23: A,B | E23: 1 | F23: tersedia dan dilaksanakan Prosedur Isolasi Energi dan tersedia LOTO Risk Card. | G23: - | H23: - | I23: - | J23: -
C24: Authorized Personel (GSI/SI/AT) | D24: A,B | E24: 1 | F24: Personel pemegang sertifikasi GSI/SI/AT tersedia lengkap di lokasi. | G24: - | H24: - | I24: - | J24: -
C25: Additional Notes / Concern matter :
C26: (Diisikan jika ada catatan tambahan / informasi penting lainnya terkait assessment preventive & Detect-control barrier yang perlu dijadikan tambahan informasi).
C30: INITIATING EVENT
C32: Hydrocarbon Release / LOPC
C34: MITIGATION MEASURES | G34: EMERGENCY RESPONSE RESOURCES
C35: =C14 -> HARDWARE (PLANT)
C36: Barrier | D36: Related to MAE | E36: Status | F36: Detail / Remarks | G36: Barrier | H36: Related to MAE | I36: Status | J36: Detail / Remarks
C37: Emergency Leak Plug / Emergency Leak control equipment | D37: A | E37: 1 | F37: Tersedia peralatan penanggulangan kebocoran pipa (temporary repair), seperti Clamp, Belzona, resin, peralatan pendukung lainnya. | G37: Emergency Communication (Radio HT) | H37: A,B | I37: 1 | J37: Tersedia Radio Komunikasi / HT sejumlah …
C38: Stardarized Electrical System | D38: A | E38: 1 | F38: Listrik di area Penerimaan yang masuk hazardous area sudah sesuai spesifikasi | G38: Emergency Alarm (Beacon) | H38: A,B | I38: 1 | J38: Tersedia Alarm / lonceng di berbagai titik sebagai emergency Alarm.
C39: Shutdown Valve (SDV) | D39: A | E39: N/A | F39: Tidak terdapat SDV | G39: Muster Point | H39: A,B | I39: 1 | J39: Tersedia area Muster Point ( rambu dan penunjuk jalur tersedia, visible), jarak cukup jauh dengan sumber api > 100 m,.
C40: Portable Gas Detector | D40: A | E40: 1 | F40: Tersedia Portable Gas Detector. | G40: APD/PPE untuk tumpahan bahan bakar (safety boot, wearpack, masker catridge) | H40: A | I40: 0.75 | J40: Tersedia safety boot, wearpack dan masker catridge sesuai dengan kebutuhan untuk penanggulangan tumpahan / kebocoran produk.(Belum memliki Baju Fire Fighting)
C41: Fixed Fire & Gas Detector System (FGDS) | D41: A,B | E41: N/A | F41: Tidak Terpasang Fixed FGDS di area penerimaan. | G41: Oil Spill Emergency Repsonse (Oil Boom,oil absorbent, skimmer, dll) | H41: A | I41: 1 | J41: Tersedia pealatan penaggulang tumpahan minyak.
C42: Lightning Protection System | D42: B | E42: 1 | F42: Apakah terpasang LPS di area pendistribution dengan jumlah, coverage dan program monitoring yang cukup. | G42: Fixed Fire Fighting Equipment/System (Fire Pump, Fire Hydran, Fire Water Line). | H42: B | I42: 1 | J42: Tersedia peralatan penanggulangan kebakaran, termasuk Fire Risk Card sesuai skenario.
C43: Grounding System | D43: B | E43: 1 | F43: Hasil Grounding System tercata pada form SF 211 | G43: Mobile emergency Response Eqipment (Fire Truck, Fire Jeep,QRU, LPG Evacuation Unit, Vacuum Truck) | H43: A,B | I43: N/A | J43: Tidak tersedia Mobile Equipment Response dan kondisi nya
C44: Oil Catcher System | D44: A | E44: 1 | F44: Tersedia oil cathcer yang sesuai persyaratan dan spesifikasi. | G44: Generator Set (Genset) untuk Power Supply saat Emergency | H44: B | I44: 1 | J44: Ttersedia 2 unit Genset yang siap pakai dan COI nya valid
C45: =C18 -> PEOPLE + PROCESS
C46: Barrier | D46: Related to MAE | E46: Status | F46: Detail / Remarks | G46: Barrier | H46: Related to MAE | I46: Status | J46: Detail / Remarks
C47: Electrical Hazardous Area Classification (EHAC) | D47: A,B | E47: - | F47: Pengklasifikasiaan peralatan dan electrical system sesuai hazardous area sudah diterapkan. | G47: Organisasi & Personel Pengendalian Tanggap Darurat yang Kompeten | H47: A,B | I47: - | J47: Sudah ditetapkan Organisasi dan Personel Pengendalian Keadaan Darurat setempat.
C48: Security Guard | D48: A,B | E48: 1 | F48: Tersedia personel dan aktivitas pengamanan saat di area penerimaan. | G48: Pedoman Pengendalian Keadaan Darurat | H48: A | I48: - | J48: Tersedia Pedoman Pengendalian Keadaan Darurat (PKD) terbaru.
C49: Pipeline ROW (signage, clearence, maintenace). | D49: A,B | E49: - | F49: Apakah Pipeline ROW (Righ-of-ways) sudah ditetapkan, diberitanda, dibersihkan dan dilakukan pemeliharaan. | G49: Bussiness Continuity Plan/Management | H49: A,B | I49: - | J49: Tersedia dokumen BCP / Skenario RAE.
C50: Prosedur Pengukuran Grounding Secara Periodik | D50: B | E50: - | F50: Apakah prosedur pengukuran tahanan grounding tersedia, dan dilaksanakan. | G50: - | H50: - | I50: - | J50: -
...

Sheet RF-05
C2: HYDROCARBON RECEIVING FACILITY
C4: MAJOR ACCIDENT HAZARD
C5: Third Party (Personel and/or Vehicle) Activities
C6: RECEIVING FACILITY & PROCESS OVERVIEW | G6: MAH REGISTER NO. | H6: DATE:
C7: Produk avtur DPPU Eltari diterima dari FT Tenau dengan jarak tempuh 19,8 Km atau + 29 Menit dengan Total Armada Bridger 3 Unit. DPPU ELtari memiliki 1 fasilitas filling shed penerimaan dan didukung oleh 1 pompa discharge kapasitas 300 Gpm. Produk avtur diterima di filling shed lalu dipompakan menuju ke tangki penerimaan dengan melewati FWS Terlebih dahulu. Rata-rata penerimaan 128 KL/Hari | G7: MAH-RF-005-Eltari | H7: 1 Maret 2023
G8: REFFERENCE DOC. : | H8: MAH Description :
G9: MAH Tahun 2022 | H9: Hydrocarbon release due to ship & third party activities at receiving facilities . The release of HC resulting major spill, fire and/or explosion, it leading to serious injury and/or multiple fatalities and environment damage.
C13: PREVENTIVE MEASURES | G13: DETECTION/CONTROL MEASURES
C14: HARDWARE (PLANT)
C15: Barrier | D15: Related to MAE | E15: Status | F15: Detail / Remarks | G15: Barrier | H15: Related to MAE | I15: Status | J15: Detail / Remarks
C16: Pipeline (Signage & marker) | D16: A,B | E16: 1 | F16: Color Code sesuai dengan Pompav Buku 4 | G16: CCTV | H16: A,B | I16: 0.5 | J16: Tersedia Radio Komunikasi / HT sejumlah …
C17: Pipeline/PLEM/SPM (Design Structural Support) | D17: A,B | E17: 1 | F17: Design untuk stucture support sudah sesuai spesifikasi. | G17: - | H17: - | I17: - | J17: -
C18: Navigation Kit & Device | D18: A,B | E18: N/A | F18: Apakah tersedia navigation kit (Fog signal, lobstruction light, Reflektor, SBNP). | G18: - | H18: - | I18: - | J18: -
C19: Breakaway Coupling | D19: A,B | E19: N/A | F19: Apakah terpasang breakaway coupling terhadap sarana penerimaan. | G19: - | H19: - | I19: - | J19: -
C20: Additional Physical Protection | D20: A,B | E20: N/A | F20: Diisikan apakah tersedia dan terpasang pengaman fisik tambahan untuk mencegah kerusakan peralatan di area penerimaan dari impact kendaraan/kapal. | G20: - | H20: - | I20: - | J20: -
C21: PEOPLE + PROCESS
C22: Barrier | D22: Related to MAE | E22: Status | F22: Detail / Remarks | G22: Barrier | H22: Related to MAE | I22: Status | J22: Detail / Remarks
C23: Program Periodically Inspection | D23: A,B | E23: - | F23: Disikan apakah ada program rutin dan periodik inspeksi. Jika diwajibkan ada dokumen COI, pastikan tersedia dokumen COI yang masih berlaku. | G23: Plant / Pipeline Patrol | H23: A,B | I23: 1 | J23: HSSE Patrol
C24: Prosedur Penerimaan Produk | D24: A,B | E24: 1 | F24: Diisikan apakah tersedia prosedur penerimaan produk yang ter-update. | G24: - | H24: - | I24: - | J24: -
C25: Prosedur Ship Approching | D25: A,B | E25: N/A | F25: Diisikan apakah tersedia prosedur Ship approching yang ter-update dan dijalankan (yang memuat batasan kondisi operasi i.e kecepatan kapal, arah dan kecepatan arus laut & angin). | G25: - | H25: - | I25: - | J25: -
C26: Prosedur Ship Transfer | D26: A,B | E26: N/A | F26: Diisikan apakah tersedia prosedur Ship transfer yang ter-update dan dijalankan. | G26: - | H26: - | I26: - | J26: -
C27: Pipeline ROW (Marking & Signage) | D27: A,B | E27: N/A | F27: Apakah Pipeline ROW (Righ-of-ways) sudah ditetapkan, diberitanda, dibersihkan dan dilakukan pemeliharaan. | G27: - | H27: - | I27: - | J27: -
C28: Community Engagement di area facility & ROW pipeline. | D28: A,B | E28: N/A | F28: Apakah ada program pelibatan komunitas di sekitar fasilitas penerimaan. | G28: - | H28: - | I28: - | J28: -
C29: Penentuan Daerah Terbatas & Terlarang (restricted area declaration) | D29: A,B | E29: 1 | F29: Apakah ada SK / penetapan Daerah terbatas & terlarang dari otoritas. | G29: - | H29: - | I29: - | J29: -
C30: Housekeeping Programme | D30: A,B | E30: 1 | F30: Housekeeping Programme | G30: - | H30: - | I30: - | J30: -
C31: Additional Notes / Concern matter :
C32: (Diisikan jika ada catatan tambahan / informasi penting lainnya terkait assessment preventive & Detect-control barrier yang perlu dijadikan tambahan informasi).
C36: INITIATING EVENT
C38: Hydrocarbon Release / LOPC
C40: MITIGATION MEASURES | G40: EMERGENCY RESPONSE RESOURCES
C41: =C14 -> HARDWARE (PLANT)
C42: Barrier | D42: Related to MAE | E42: Status | F42: Detail / Remarks | G42: Barrier | H42: Related to MAE | I42: Status | J42: Detail / Remarks
C43: Emergency Leak Plug / Emergency Leak control equipment | D43: A | E43: 1 | F43: Tersedia peralatan penanggulangan kebocoran pipa (temporary repair), seperti Clamp, Belzona, resin, peralatan pendukung lainnya. | G43: Emergency Communication (Radio HT) | H43: A,B | I43: 1 | J43: Tersedia Radio Komunikasi / HT sesuai dengan kebutuhan (Jumlah dan spec.) dan berfungsi dengan baik.
C44: Stardarized Electrical System | D44: A | E44: 1 | F44: Apakah Peralatan Listrik di area Penerimaan yang masuk hazardous area sudah sesuai spesifikasi? | G44: Emergency Alarm (Beacon) | H44: A,B | I44: 1 | J44: Tersedia Alarm / lonceng di berbagai titik sebagai emergency Alarm.
C45: Shutdown Valve (SDV) | D45: A | E45: N/A | F45: Terpasang SDV di jalur pipa penerimaan. | G45: Muster Point | H45: A,B | I45: 1 | J45: Tersedia area Muster Point ( rambu dan penunjuk jalur tersedia, visible), jarak cukup jauh dengan sumber api > 100 m,.
C46: Portable Gas Detector | D46: A | E46: 1 | F46: Ada Portable Gas Detector MSA Altair 5X | G46: APD/PPE untuk tumpahan bahan bakar (safety boot, wearpack, masker catridge) | H46: A | I46: 1 | J46: Tersedia safety boot, wearpack dan masker catridge sesuai dengan kebutuhan untuk penanggulangan tumpahan / kebocoran produk.
C47: Fixed Fire & Gas Detector System (FGDS) | D47: A,B | E47: N/A | F47: Terpasang Fixed FGDS di area penerimaan. | G47: Oil Spill Emergency Repsonse (Oil Boom,oil absorbent, skimmer, dll) | H47: A | I47: 1 | J47: Tersedia peralatan penaggulang tumpahan minyak oil Absorbent disetiap kendaraan
C48: Lightning Protection System | D48: B | E48: 1 | F48: Apakah terpasang LPS di area pendistribution dengan jumlah, coverage dan program monitoring yang cukup. | G48: Fixed Fire Fighting Equipment/System (Fire Pump, Fire Hydran, Fire Water Line). | H48: B | I48: 1 | J48: Tersedia peralatan penanggulangan kebakaran 1 Unit Fore Pump, termasuk Fire Risk Card sesuai skenario.
C49: Grounding System | D49: B | E49: 1 | F49: Apakah terpasang Grounding system yang cukup danter-instalasi dengan baik. | G49: Mobile emergency Response Eqipment (Fire Truck, Fire Jeep,QRU, LPG Evacuation Unit, Vacuum Truck) | H49: A,B | I49: 1 | J49: tersedia Mobile Equipment Response dan kondisi nya ( 1 Unit Mobile Fire Pump)
C50: Oil Catcher System | D50: A | E50: 1 | F50: Tersedia oil cathcer yang sesuai persyaratan dan spesifikasi. | G50: Generator Set (Genset) untuk Power Supply saat Emergency | H50: B | I50: 1 | J50: Tersedia 2 unit Genset yang siap pakai dan COI nya valid
...

Sheet RF-06
C2: HYDROCARBON RECEIVING FACILITY
C4: MAJOR ACCIDENT HAZARD
C5: Normal Operation Activity (Inc. Sampling Activity)
C6: RECEIVING FACILITY & PROCESS OVERVIEW | G6: MAH REGISTER NO. | H6: DATE:
C7: Produk avtur DPPU Eltari diterima dari FT Tenau dengan jarak tempuh 19,8 Km atau + 29 Menit dengan Total Armada Bridger 3 Unit. DPPU ELtari memiliki 1 fasilitas filling shed penerimaan dan didukung oleh 1 pompa discharge kapasitas 300 Gpm. Produk avtur diterima di filling shed lalu dipompakan menuju ke tangki penerimaan dengan melewati FWS Terlebih dahulu. Rata-rata penerimaan 128 KL/Hari | G7: MAH-RF-006-Eltari | H7: 1 Maret 2023
G8: REFFERENCE DOC. : | H8: MAH Description :
G9: MAH Tahun 2022 | H9: Hydrocarbon release due to Normal Operation Activity (Truck/Ship Unloading,including Sampling Activity). The release of HC resulting major spill, fire and/or explosion, it leading to serious injury and/or multiple fatalities and environment damage.
C13: PREVENTIVE MEASURES | G13: DETECTION/CONTROL MEASURES
C14: HARDWARE (PLANT)
C15: Barrier | D15: Related to MAE | E15: Status | F15: Detail / Remarks | G15: Barrier | H15: Related to MAE | I15: Status | J15: Detail / Remarks
C16: Pipeline Specification (Design Material Selection) | D16: A,B | E16: 1 | F16: API 5L Grade B Schedule 80 Dia. 4" | G16: CCTV | H16: A,B | I16: 0.5 | J16: ada 8 CCTV hanya 4 yang berfungsi
C17: Product Pump Specification (Design Material Selection) | D17: A,B | E17: 1 | F17: Centrifugal Diesel Pump | G17: Mekanikal Valve untuk proteksi overpressure / vacuum (PRV/PSV/ PVV / Vent / Free Vent) | H17: A,B | I17: 1 | J17: Diisikan apakah peralatan tersebut terpasang sesuai design specification, dan dilakukan inspeksi secara rutin (jika wajib COI, pastikan COI nya valid).
C18: Standarized Sampling Apparatus | D18: A,B | E18: 1 | F18: ISO 3170 (IP Petroleum Measurement Manual, Part VI, Sampling Item 1 Manual Methods). | G18: Actuated Isolation valve (MOV) | H18: A | I18: N/A | J18: Tidak memiliki MOV
C19: Designated Sampling Point | D19: A,B | E19: 1 | F19: American Society for Testing and Materials (ASTM), Standard Practice for Manual Sampling of Petroleum and Petroleum Produk (ASTM D4057). | G19: - | H19: - | I19: - | J19: -
C20: PEOPLE + PROCESS
C21: Barrier | D21: Related to MAE | E21: Status | F21: Detail / Remarks | G21: Barrier | H21: Related to MAE | I21: Status | J21: Detail / Remarks
C22: Program Periodically Inspection | D22: A,B | E22: 1 | F22: Disikan apakah ada program rutin dan periodik inspeksi. Jika diwajibkan ada dokumen COI, pastikan tersedia dokumen COI yang masih berlaku. | G22: Plant / Pipeline Patrol | H22: A,B | I22: - | J22: Ada program supervisi / pengamatan dari operator / supervisor / inspektor / HSE, dilakukan rutin setiap periode nya, ada bukti nya
C23: Prosedur Penerimaan Produk | D23: A,B | E23: 1 | F23: Pompav Buku 2 Pengendalian Mutu BBMP | G23: - | H23: - | I23: - | J23: -
C24: Prosedur Sampling | D24: A,B | E24: 1 | F24: Apakah tersedia dan dilaksanakan Prosedur Sampling dan Personel pelaksana yang kompeten. | G24: - | H24: - | I24: - | J24: -
C25: Additional Notes / Concern matter :
C26: (Diisikan jika ada catatan tambahan / informasi penting lainnya terkait assessment preventive & Detect-control barrier yang perlu dijadikan tambahan informasi).
C30: INITIATING EVENT
C32: Hydrocarbon Release / LOPC
C34: MITIGATION MEASURES | G34: EMERGENCY RESPONSE RESOURCES
C35: =C14 -> HARDWARE (PLANT)
C36: Barrier | D36: Related to MAE | E36: Status | F36: Detail / Remarks | G36: Barrier | H36: Related to MAE | I36: Status | J36: Detail / Remarks
